[2023-06-06 23:57:40,297: INFO: main: welcome to my custom log]
[2023-06-08 21:22:16,020: INFO: main: >>>>>>> stage Data Ingestion stage started<<<<<]
[2023-06-08 21:22:16,026: INFO: common: yaml file:config\config.yaml loaded successfully]
[2023-06-08 21:22:16,031: INFO: common: yaml file:params.yaml loaded successfully]
[2023-06-08 21:22:16,033: ERROR: main: "'ConfigBox' object has no attribute 'artifacts_root'"]
Traceback (most recent call last):
  File "box\box.py", line 503, in box.box.Box.__getitem__
KeyError: 'artifacts_root'

The above exception was the direct cause of the following exception:

Traceback (most recent call last):
  File "box\box.py", line 536, in box.box.Box.__getattr__
  File "box\box.py", line 524, in box.box.Box.__getitem__
box.exceptions.BoxKeyError: "'artifacts_root'"

During handling of the above exception, another exception occurred:

Traceback (most recent call last):
  File "box\box.py", line 538, in box.box.Box.__getattr__
AttributeError: 'ConfigBox' object has no attribute 'artifacts_root'

The above exception was the direct cause of the following exception:

Traceback (most recent call last):
  File "box\config_box.py", line 28, in box.config_box.ConfigBox.__getattr__
  File "box\box.py", line 552, in box.box.Box.__getattr__
box.exceptions.BoxKeyError: "'ConfigBox' object has no attribute 'artifacts_root'"

During handling of the above exception, another exception occurred:

Traceback (most recent call last):
  File "box\box.py", line 503, in box.box.Box.__getitem__
KeyError: 'artifacts_root'

The above exception was the direct cause of the following exception:

Traceback (most recent call last):
  File "box\box.py", line 536, in box.box.Box.__getattr__
  File "box\box.py", line 524, in box.box.Box.__getitem__
box.exceptions.BoxKeyError: "'artifacts_root'"

During handling of the above exception, another exception occurred:

Traceback (most recent call last):
  File "box\box.py", line 538, in box.box.Box.__getattr__
AttributeError: 'ConfigBox' object has no attribute 'artifacts_root'

The above exception was the direct cause of the following exception:

Traceback (most recent call last):
  File "main.py", line 10, in <module>
    data_ingestion.main()
  File "f:\ineuron\project\chicken-disease-classification\src\chickenClassifier\pipeline\stage_01_data_ingestion.py", line 13, in main
    config = ConfigurationManager()
  File "f:\ineuron\project\chicken-disease-classification\src\chickenClassifier\config\configuration.py", line 11, in __init__
    create_directories([self.config.artifacts_root])
  File "box\config_box.py", line 30, in box.config_box.ConfigBox.__getattr__
  File "box\box.py", line 552, in box.box.Box.__getattr__
box.exceptions.BoxKeyError: "'ConfigBox' object has no attribute 'artifacts_root'"
[2023-06-08 21:23:33,105: INFO: main: >>>>>>> stage Data Ingestion stage started<<<<<]
[2023-06-08 21:23:33,109: INFO: common: yaml file:config\config.yaml loaded successfully]
[2023-06-08 21:23:33,110: INFO: common: yaml file:params.yaml loaded successfully]
[2023-06-08 21:23:33,112: INFO: common: created directory at: artifacts]
[2023-06-08 21:23:33,114: INFO: common: created directory at: artifacts/data_ingestion]
[2023-06-08 21:23:33,115: ERROR: main: __init__() got an unexpected keyword argument 'source_URL']
Traceback (most recent call last):
  File "main.py", line 10, in <module>
    data_ingestion.main()
  File "f:\ineuron\project\chicken-disease-classification\src\chickenClassifier\pipeline\stage_01_data_ingestion.py", line 14, in main
    data_ingestion_config = config.get_data_ingestion_config()
  File "f:\ineuron\project\chicken-disease-classification\src\chickenClassifier\config\configuration.py", line 18, in get_data_ingestion_config
    data_ingestion_config = DataIngestionConfig(
TypeError: __init__() got an unexpected keyword argument 'source_URL'
[2023-06-08 21:25:13,382: INFO: main: >>>>>>> stage Data Ingestion stage started<<<<<]
[2023-06-08 21:25:13,386: INFO: common: yaml file:config\config.yaml loaded successfully]
[2023-06-08 21:25:13,388: INFO: common: yaml file:params.yaml loaded successfully]
[2023-06-08 21:25:13,389: INFO: common: created directory at: artifacts]
[2023-06-08 21:25:13,390: INFO: common: created directory at: artifacts/data_ingestion]
[2023-06-08 21:25:13,391: ERROR: main: 'DataIngestionConfig' object has no attribute 'sourceURL']
Traceback (most recent call last):
  File "main.py", line 10, in <module>
    data_ingestion.main()
  File "f:\ineuron\project\chicken-disease-classification\src\chickenClassifier\pipeline\stage_01_data_ingestion.py", line 16, in main
    data_ingestion.download_file()
  File "f:\ineuron\project\chicken-disease-classification\src\chickenClassifier\components\data_ingestion.py", line 19, in download_file
    url = self.config.sourceURL,
AttributeError: 'DataIngestionConfig' object has no attribute 'sourceURL'
[2023-06-08 21:25:35,125: INFO: main: >>>>>>> stage Data Ingestion stage started<<<<<]
[2023-06-08 21:25:35,131: INFO: common: yaml file:config\config.yaml loaded successfully]
[2023-06-08 21:25:35,133: INFO: common: yaml file:params.yaml loaded successfully]
[2023-06-08 21:25:35,134: INFO: common: created directory at: artifacts]
[2023-06-08 21:25:35,135: INFO: common: created directory at: artifacts/data_ingestion]
[2023-06-08 21:26:18,020: ERROR: main: <urlopen error [WinError 10060] A connection attempt failed because the connected party did not properly respond after a period of time, or established connection failed because connected host has failed to respond>]
Traceback (most recent call last):
  File "C:\Users\Zaban\anaconda3\envs\chicken\lib\urllib\request.py", line 1354, in do_open
    h.request(req.get_method(), req.selector, req.data, headers,
  File "C:\Users\Zaban\anaconda3\envs\chicken\lib\http\client.py", line 1256, in request
    self._send_request(method, url, body, headers, encode_chunked)
  File "C:\Users\Zaban\anaconda3\envs\chicken\lib\http\client.py", line 1302, in _send_request
    self.endheaders(body, encode_chunked=encode_chunked)
  File "C:\Users\Zaban\anaconda3\envs\chicken\lib\http\client.py", line 1251, in endheaders
    self._send_output(message_body, encode_chunked=encode_chunked)
  File "C:\Users\Zaban\anaconda3\envs\chicken\lib\http\client.py", line 1011, in _send_output
    self.send(msg)
  File "C:\Users\Zaban\anaconda3\envs\chicken\lib\http\client.py", line 951, in send
    self.connect()
  File "C:\Users\Zaban\anaconda3\envs\chicken\lib\http\client.py", line 1418, in connect
    super().connect()
  File "C:\Users\Zaban\anaconda3\envs\chicken\lib\http\client.py", line 922, in connect
    self.sock = self._create_connection(
  File "C:\Users\Zaban\anaconda3\envs\chicken\lib\socket.py", line 808, in create_connection
    raise err
  File "C:\Users\Zaban\anaconda3\envs\chicken\lib\socket.py", line 796, in create_connection
    sock.connect(sa)
TimeoutError: [WinError 10060] A connection attempt failed because the connected party did not properly respond after a period of time, or established connection failed because connected host has failed to respond

During handling of the above exception, another exception occurred:

Traceback (most recent call last):
  File "main.py", line 10, in <module>
    data_ingestion.main()
  File "f:\ineuron\project\chicken-disease-classification\src\chickenClassifier\pipeline\stage_01_data_ingestion.py", line 16, in main
    data_ingestion.download_file()
  File "f:\ineuron\project\chicken-disease-classification\src\chickenClassifier\components\data_ingestion.py", line 18, in download_file
    filename, headers = request.urlretrieve(
  File "C:\Users\Zaban\anaconda3\envs\chicken\lib\urllib\request.py", line 247, in urlretrieve
    with contextlib.closing(urlopen(url, data)) as fp:
  File "C:\Users\Zaban\anaconda3\envs\chicken\lib\urllib\request.py", line 222, in urlopen
    return opener.open(url, data, timeout)
  File "C:\Users\Zaban\anaconda3\envs\chicken\lib\urllib\request.py", line 531, in open
    response = meth(req, response)
  File "C:\Users\Zaban\anaconda3\envs\chicken\lib\urllib\request.py", line 640, in http_response
    response = self.parent.error(
  File "C:\Users\Zaban\anaconda3\envs\chicken\lib\urllib\request.py", line 563, in error
    result = self._call_chain(*args)
  File "C:\Users\Zaban\anaconda3\envs\chicken\lib\urllib\request.py", line 502, in _call_chain
    result = func(*args)
  File "C:\Users\Zaban\anaconda3\envs\chicken\lib\urllib\request.py", line 755, in http_error_302
    return self.parent.open(new, timeout=req.timeout)
  File "C:\Users\Zaban\anaconda3\envs\chicken\lib\urllib\request.py", line 525, in open
    response = self._open(req, data)
  File "C:\Users\Zaban\anaconda3\envs\chicken\lib\urllib\request.py", line 542, in _open
    result = self._call_chain(self.handle_open, protocol, protocol +
  File "C:\Users\Zaban\anaconda3\envs\chicken\lib\urllib\request.py", line 502, in _call_chain
    result = func(*args)
  File "C:\Users\Zaban\anaconda3\envs\chicken\lib\urllib\request.py", line 1397, in https_open
    return self.do_open(http.client.HTTPSConnection, req,
  File "C:\Users\Zaban\anaconda3\envs\chicken\lib\urllib\request.py", line 1357, in do_open
    raise URLError(err)
urllib.error.URLError: <urlopen error [WinError 10060] A connection attempt failed because the connected party did not properly respond after a period of time, or established connection failed because connected host has failed to respond>
[2023-06-09 01:43:20,551: INFO: main: >>>>>>> stage Data Ingestion stage started<<<<<]
[2023-06-09 01:43:20,556: INFO: common: yaml file:config\config.yaml loaded successfully]
[2023-06-09 01:43:20,560: INFO: common: yaml file:params.yaml loaded successfully]
[2023-06-09 01:43:20,561: INFO: common: created directory at: artifacts]
[2023-06-09 01:43:20,562: INFO: common: created directory at: artifacts/data_ingestion]
[2023-06-09 01:43:20,562: ERROR: main: "'ConfigBox' object has no attribute 'local_data_file'"]
Traceback (most recent call last):
  File "box\box.py", line 503, in box.box.Box.__getitem__
KeyError: 'local_data_file'

The above exception was the direct cause of the following exception:

Traceback (most recent call last):
  File "box\box.py", line 536, in box.box.Box.__getattr__
  File "box\box.py", line 524, in box.box.Box.__getitem__
box.exceptions.BoxKeyError: "'local_data_file'"

During handling of the above exception, another exception occurred:

Traceback (most recent call last):
  File "box\box.py", line 538, in box.box.Box.__getattr__
AttributeError: 'ConfigBox' object has no attribute 'local_data_file'

The above exception was the direct cause of the following exception:

Traceback (most recent call last):
  File "box\config_box.py", line 28, in box.config_box.ConfigBox.__getattr__
  File "box\box.py", line 552, in box.box.Box.__getattr__
box.exceptions.BoxKeyError: "'ConfigBox' object has no attribute 'local_data_file'"

During handling of the above exception, another exception occurred:

Traceback (most recent call last):
  File "box\box.py", line 503, in box.box.Box.__getitem__
KeyError: 'local_data_file'

The above exception was the direct cause of the following exception:

Traceback (most recent call last):
  File "box\box.py", line 536, in box.box.Box.__getattr__
  File "box\box.py", line 524, in box.box.Box.__getitem__
box.exceptions.BoxKeyError: "'local_data_file'"

During handling of the above exception, another exception occurred:

Traceback (most recent call last):
  File "box\box.py", line 538, in box.box.Box.__getattr__
AttributeError: 'ConfigBox' object has no attribute 'local_data_file'

The above exception was the direct cause of the following exception:

Traceback (most recent call last):
  File "main.py", line 10, in <module>
    data_ingestion.main()
  File "f:\ineuron\project\chicken-disease-classification\src\chickenClassifier\pipeline\stage_01_data_ingestion.py", line 14, in main
    data_ingestion_config = config.get_data_ingestion_config()
  File "f:\ineuron\project\chicken-disease-classification\src\chickenClassifier\config\configuration.py", line 21, in get_data_ingestion_config
    local_data_file=config.local_data_file,
  File "box\config_box.py", line 30, in box.config_box.ConfigBox.__getattr__
  File "box\box.py", line 552, in box.box.Box.__getattr__
box.exceptions.BoxKeyError: "'ConfigBox' object has no attribute 'local_data_file'"
[2023-06-09 01:44:17,428: INFO: main: >>>>>>> stage Data Ingestion stage started<<<<<]
[2023-06-09 01:44:17,432: INFO: common: yaml file:config\config.yaml loaded successfully]
[2023-06-09 01:44:17,435: INFO: common: yaml file:params.yaml loaded successfully]
[2023-06-09 01:44:17,436: INFO: common: created directory at: artifacts]
[2023-06-09 01:44:17,443: INFO: common: created directory at: artifacts/data_ingestion]
[2023-06-09 01:44:17,459: ERROR: main: "'ConfigBox' object has no attribute 'saparate_files'"]
Traceback (most recent call last):
  File "box\box.py", line 503, in box.box.Box.__getitem__
KeyError: 'saparate_files'

The above exception was the direct cause of the following exception:

Traceback (most recent call last):
  File "box\box.py", line 536, in box.box.Box.__getattr__
  File "box\box.py", line 524, in box.box.Box.__getitem__
box.exceptions.BoxKeyError: "'saparate_files'"

During handling of the above exception, another exception occurred:

Traceback (most recent call last):
  File "box\box.py", line 538, in box.box.Box.__getattr__
AttributeError: 'ConfigBox' object has no attribute 'saparate_files'

The above exception was the direct cause of the following exception:

Traceback (most recent call last):
  File "box\config_box.py", line 28, in box.config_box.ConfigBox.__getattr__
  File "box\box.py", line 552, in box.box.Box.__getattr__
box.exceptions.BoxKeyError: "'ConfigBox' object has no attribute 'saparate_files'"

During handling of the above exception, another exception occurred:

Traceback (most recent call last):
  File "box\box.py", line 503, in box.box.Box.__getitem__
KeyError: 'saparate_files'

The above exception was the direct cause of the following exception:

Traceback (most recent call last):
  File "box\box.py", line 536, in box.box.Box.__getattr__
  File "box\box.py", line 524, in box.box.Box.__getitem__
box.exceptions.BoxKeyError: "'saparate_files'"

During handling of the above exception, another exception occurred:

Traceback (most recent call last):
  File "box\box.py", line 538, in box.box.Box.__getattr__
AttributeError: 'ConfigBox' object has no attribute 'saparate_files'

The above exception was the direct cause of the following exception:

Traceback (most recent call last):
  File "main.py", line 10, in <module>
    data_ingestion.main()
  File "f:\ineuron\project\chicken-disease-classification\src\chickenClassifier\pipeline\stage_01_data_ingestion.py", line 14, in main
    data_ingestion_config = config.get_data_ingestion_config()
  File "f:\ineuron\project\chicken-disease-classification\src\chickenClassifier\config\configuration.py", line 22, in get_data_ingestion_config
    unzip_dir=config.saparate_files
  File "box\config_box.py", line 30, in box.config_box.ConfigBox.__getattr__
  File "box\box.py", line 552, in box.box.Box.__getattr__
box.exceptions.BoxKeyError: "'ConfigBox' object has no attribute 'saparate_files'"
[2023-06-09 01:45:13,586: INFO: main: >>>>>>> stage Data Ingestion stage started<<<<<]
[2023-06-09 01:45:13,593: INFO: common: yaml file:config\config.yaml loaded successfully]
[2023-06-09 01:45:13,595: INFO: common: yaml file:params.yaml loaded successfully]
[2023-06-09 01:45:13,596: INFO: common: created directory at: artifacts]
[2023-06-09 01:45:13,597: INFO: common: created directory at: artifacts/data_ingestion]
[2023-06-09 01:45:13,597: ERROR: main: "'ConfigBox' object has no attribute 'saparate_files'"]
Traceback (most recent call last):
  File "box\box.py", line 503, in box.box.Box.__getitem__
KeyError: 'saparate_files'

The above exception was the direct cause of the following exception:

Traceback (most recent call last):
  File "box\box.py", line 536, in box.box.Box.__getattr__
  File "box\box.py", line 524, in box.box.Box.__getitem__
box.exceptions.BoxKeyError: "'saparate_files'"

During handling of the above exception, another exception occurred:

Traceback (most recent call last):
  File "box\box.py", line 538, in box.box.Box.__getattr__
AttributeError: 'ConfigBox' object has no attribute 'saparate_files'

The above exception was the direct cause of the following exception:

Traceback (most recent call last):
  File "box\config_box.py", line 28, in box.config_box.ConfigBox.__getattr__
  File "box\box.py", line 552, in box.box.Box.__getattr__
box.exceptions.BoxKeyError: "'ConfigBox' object has no attribute 'saparate_files'"

During handling of the above exception, another exception occurred:

Traceback (most recent call last):
  File "box\box.py", line 503, in box.box.Box.__getitem__
KeyError: 'saparate_files'

The above exception was the direct cause of the following exception:

Traceback (most recent call last):
  File "box\box.py", line 536, in box.box.Box.__getattr__
  File "box\box.py", line 524, in box.box.Box.__getitem__
box.exceptions.BoxKeyError: "'saparate_files'"

During handling of the above exception, another exception occurred:

Traceback (most recent call last):
  File "box\box.py", line 538, in box.box.Box.__getattr__
AttributeError: 'ConfigBox' object has no attribute 'saparate_files'

The above exception was the direct cause of the following exception:

Traceback (most recent call last):
  File "main.py", line 10, in <module>
    data_ingestion.main()
  File "f:\ineuron\project\chicken-disease-classification\src\chickenClassifier\pipeline\stage_01_data_ingestion.py", line 14, in main
    data_ingestion_config = config.get_data_ingestion_config()
  File "f:\ineuron\project\chicken-disease-classification\src\chickenClassifier\config\configuration.py", line 22, in get_data_ingestion_config
    saparate_files=config.saparate_files
  File "box\config_box.py", line 30, in box.config_box.ConfigBox.__getattr__
  File "box\box.py", line 552, in box.box.Box.__getattr__
box.exceptions.BoxKeyError: "'ConfigBox' object has no attribute 'saparate_files'"
[2023-06-09 01:45:45,314: INFO: main: >>>>>>> stage Data Ingestion stage started<<<<<]
[2023-06-09 01:45:45,318: INFO: common: yaml file:config\config.yaml loaded successfully]
[2023-06-09 01:45:45,320: INFO: common: yaml file:params.yaml loaded successfully]
[2023-06-09 01:45:45,321: INFO: common: created directory at: artifacts]
[2023-06-09 01:45:45,322: INFO: common: created directory at: artifacts/data_ingestion]
[2023-06-09 01:45:45,323: ERROR: main: "'ConfigBox' object has no attribute 'saparate_files'"]
Traceback (most recent call last):
  File "box\box.py", line 503, in box.box.Box.__getitem__
KeyError: 'saparate_files'

The above exception was the direct cause of the following exception:

Traceback (most recent call last):
  File "box\box.py", line 536, in box.box.Box.__getattr__
  File "box\box.py", line 524, in box.box.Box.__getitem__
box.exceptions.BoxKeyError: "'saparate_files'"

During handling of the above exception, another exception occurred:

Traceback (most recent call last):
  File "box\box.py", line 538, in box.box.Box.__getattr__
AttributeError: 'ConfigBox' object has no attribute 'saparate_files'

The above exception was the direct cause of the following exception:

Traceback (most recent call last):
  File "box\config_box.py", line 28, in box.config_box.ConfigBox.__getattr__
  File "box\box.py", line 552, in box.box.Box.__getattr__
box.exceptions.BoxKeyError: "'ConfigBox' object has no attribute 'saparate_files'"

During handling of the above exception, another exception occurred:

Traceback (most recent call last):
  File "box\box.py", line 503, in box.box.Box.__getitem__
KeyError: 'saparate_files'

The above exception was the direct cause of the following exception:

Traceback (most recent call last):
  File "box\box.py", line 536, in box.box.Box.__getattr__
  File "box\box.py", line 524, in box.box.Box.__getitem__
box.exceptions.BoxKeyError: "'saparate_files'"

During handling of the above exception, another exception occurred:

Traceback (most recent call last):
  File "box\box.py", line 538, in box.box.Box.__getattr__
AttributeError: 'ConfigBox' object has no attribute 'saparate_files'

The above exception was the direct cause of the following exception:

Traceback (most recent call last):
  File "main.py", line 10, in <module>
    data_ingestion.main()
  File "f:\ineuron\project\chicken-disease-classification\src\chickenClassifier\pipeline\stage_01_data_ingestion.py", line 14, in main
    data_ingestion_config = config.get_data_ingestion_config()
  File "f:\ineuron\project\chicken-disease-classification\src\chickenClassifier\config\configuration.py", line 22, in get_data_ingestion_config
    saparate_files=config.saparate_files
  File "box\config_box.py", line 30, in box.config_box.ConfigBox.__getattr__
  File "box\box.py", line 552, in box.box.Box.__getattr__
box.exceptions.BoxKeyError: "'ConfigBox' object has no attribute 'saparate_files'"
[2023-06-09 01:46:02,838: INFO: main: >>>>>>> stage Data Ingestion stage started<<<<<]
[2023-06-09 01:46:02,842: INFO: common: yaml file:config\config.yaml loaded successfully]
[2023-06-09 01:46:02,844: INFO: common: yaml file:params.yaml loaded successfully]
[2023-06-09 01:46:02,846: INFO: common: created directory at: artifacts]
[2023-06-09 01:46:02,868: INFO: common: created directory at: artifacts/data_ingestion]
[2023-06-09 01:46:02,870: ERROR: main: name 'KaggleApi' is not defined]
Traceback (most recent call last):
  File "main.py", line 10, in <module>
    data_ingestion.main()
  File "f:\ineuron\project\chicken-disease-classification\src\chickenClassifier\pipeline\stage_01_data_ingestion.py", line 16, in main
    data_ingestion.download_file()
  File "f:\ineuron\project\chicken-disease-classification\src\chickenClassifier\components\data_ingestion.py", line 20, in download_file
    api = KaggleApi()
NameError: name 'KaggleApi' is not defined
[2023-06-09 01:59:51,505: INFO: main: >>>>>>> stage Data Ingestion stage started<<<<<]
[2023-06-09 01:59:51,511: INFO: common: yaml file:config\config.yaml loaded successfully]
[2023-06-09 01:59:51,513: INFO: common: yaml file:params.yaml loaded successfully]
[2023-06-09 01:59:51,514: INFO: common: created directory at: artifacts]
[2023-06-09 01:59:51,515: INFO: common: created directory at: artifacts/data_ingestion]
[2023-06-09 01:59:51,818: ERROR: main: Could not find kaggle.json. Make sure it's located in C:\Users\Zaban\.kaggle. Or use the environment method.]
Traceback (most recent call last):
  File "main.py", line 10, in <module>
    data_ingestion.main()
  File "f:\ineuron\project\chicken-disease-classification\src\chickenClassifier\pipeline\stage_01_data_ingestion.py", line 16, in main
    data_ingestion.download_file()
  File "f:\ineuron\project\chicken-disease-classification\src\chickenClassifier\components\data_ingestion.py", line 21, in download_file
    from kaggle.api.kaggle_api_extended import KaggleApi
  File "C:\Users\Zaban\anaconda3\envs\chicken\lib\site-packages\kaggle\__init__.py", line 23, in <module>
    api.authenticate()
  File "C:\Users\Zaban\anaconda3\envs\chicken\lib\site-packages\kaggle\api\kaggle_api_extended.py", line 164, in authenticate
    raise IOError('Could not find {}. Make sure it\'s located in'
OSError: Could not find kaggle.json. Make sure it's located in C:\Users\Zaban\.kaggle. Or use the environment method.
[2023-06-09 02:00:14,264: INFO: main: >>>>>>> stage Data Ingestion stage started<<<<<]
[2023-06-09 02:00:14,272: INFO: common: yaml file:config\config.yaml loaded successfully]
[2023-06-09 02:00:14,274: INFO: common: yaml file:params.yaml loaded successfully]
[2023-06-09 02:00:14,275: INFO: common: created directory at: artifacts]
[2023-06-09 02:00:14,276: INFO: common: created directory at: artifacts/data_ingestion]
[2023-06-09 02:00:14,570: ERROR: main: Could not find kaggle.json. Make sure it's located in C:\Users\Zaban\.kaggle. Or use the environment method.]
Traceback (most recent call last):
  File "main.py", line 10, in <module>
    data_ingestion.main()
  File "f:\ineuron\project\chicken-disease-classification\src\chickenClassifier\pipeline\stage_01_data_ingestion.py", line 16, in main
    data_ingestion.download_file()
  File "f:\ineuron\project\chicken-disease-classification\src\chickenClassifier\components\data_ingestion.py", line 21, in download_file
    from kaggle.api.kaggle_api_extended import KaggleApi
  File "C:\Users\Zaban\anaconda3\envs\chicken\lib\site-packages\kaggle\__init__.py", line 23, in <module>
    api.authenticate()
  File "C:\Users\Zaban\anaconda3\envs\chicken\lib\site-packages\kaggle\api\kaggle_api_extended.py", line 164, in authenticate
    raise IOError('Could not find {}. Make sure it\'s located in'
OSError: Could not find kaggle.json. Make sure it's located in C:\Users\Zaban\.kaggle. Or use the environment method.
[2023-06-09 02:00:42,286: INFO: main: >>>>>>> stage Data Ingestion stage started<<<<<]
[2023-06-09 02:00:42,295: INFO: common: yaml file:config\config.yaml loaded successfully]
[2023-06-09 02:00:42,297: INFO: common: yaml file:params.yaml loaded successfully]
[2023-06-09 02:00:42,303: INFO: common: created directory at: artifacts]
[2023-06-09 02:00:42,321: INFO: common: created directory at: artifacts/data_ingestion]
[2023-06-09 02:00:42,324: ERROR: main: str expected, not NoneType]
Traceback (most recent call last):
  File "main.py", line 10, in <module>
    data_ingestion.main()
  File "f:\ineuron\project\chicken-disease-classification\src\chickenClassifier\pipeline\stage_01_data_ingestion.py", line 16, in main
    data_ingestion.download_file()
  File "f:\ineuron\project\chicken-disease-classification\src\chickenClassifier\components\data_ingestion.py", line 21, in download_file
    os.environ['KAGGLE_USERNAME'] = kaggle_username
  File "C:\Users\Zaban\anaconda3\envs\chicken\lib\os.py", line 680, in __setitem__
    value = self.encodevalue(value)
  File "C:\Users\Zaban\anaconda3\envs\chicken\lib\os.py", line 736, in check_str
    raise TypeError("str expected, not %s" % type(value).__name__)
TypeError: str expected, not NoneType
[2023-06-09 02:01:18,949: INFO: main: >>>>>>> stage Data Ingestion stage started<<<<<]
[2023-06-09 02:01:18,953: INFO: common: yaml file:config\config.yaml loaded successfully]
[2023-06-09 02:01:18,956: INFO: common: yaml file:params.yaml loaded successfully]
[2023-06-09 02:01:18,958: INFO: common: created directory at: artifacts]
[2023-06-09 02:01:18,983: INFO: common: created directory at: artifacts/data_ingestion]
[2023-06-09 02:01:19,011: ERROR: main: str expected, not NoneType]
Traceback (most recent call last):
  File "main.py", line 10, in <module>
    data_ingestion.main()
  File "f:\ineuron\project\chicken-disease-classification\src\chickenClassifier\pipeline\stage_01_data_ingestion.py", line 16, in main
    data_ingestion.download_file()
  File "f:\ineuron\project\chicken-disease-classification\src\chickenClassifier\components\data_ingestion.py", line 21, in download_file
    os.environ['KAGGLE_USERNAME'] = kaggle_username
  File "C:\Users\Zaban\anaconda3\envs\chicken\lib\os.py", line 680, in __setitem__
    value = self.encodevalue(value)
  File "C:\Users\Zaban\anaconda3\envs\chicken\lib\os.py", line 736, in check_str
    raise TypeError("str expected, not %s" % type(value).__name__)
TypeError: str expected, not NoneType
[2023-06-09 02:01:41,059: INFO: main: >>>>>>> stage Data Ingestion stage started<<<<<]
[2023-06-09 02:01:41,064: INFO: common: yaml file:config\config.yaml loaded successfully]
[2023-06-09 02:01:41,087: INFO: common: yaml file:params.yaml loaded successfully]
[2023-06-09 02:01:41,090: INFO: common: created directory at: artifacts]
[2023-06-09 02:01:41,093: INFO: common: created directory at: artifacts/data_ingestion]
[2023-06-09 02:01:41,118: ERROR: main: str expected, not NoneType]
Traceback (most recent call last):
  File "main.py", line 10, in <module>
    data_ingestion.main()
  File "f:\ineuron\project\chicken-disease-classification\src\chickenClassifier\pipeline\stage_01_data_ingestion.py", line 16, in main
    data_ingestion.download_file()
  File "f:\ineuron\project\chicken-disease-classification\src\chickenClassifier\components\data_ingestion.py", line 21, in download_file
    os.environ['KAGGLE_USERNAME'] = kaggle_username
  File "C:\Users\Zaban\anaconda3\envs\chicken\lib\os.py", line 680, in __setitem__
    value = self.encodevalue(value)
  File "C:\Users\Zaban\anaconda3\envs\chicken\lib\os.py", line 736, in check_str
    raise TypeError("str expected, not %s" % type(value).__name__)
TypeError: str expected, not NoneType
[2023-06-09 02:02:07,004: INFO: main: >>>>>>> stage Data Ingestion stage started<<<<<]
[2023-06-09 02:02:07,013: INFO: common: yaml file:config\config.yaml loaded successfully]
[2023-06-09 02:02:07,017: INFO: common: yaml file:params.yaml loaded successfully]
[2023-06-09 02:02:07,018: INFO: common: created directory at: artifacts]
[2023-06-09 02:02:07,030: INFO: common: created directory at: artifacts/data_ingestion]
[2023-06-09 02:02:07,078: ERROR: main: str expected, not NoneType]
Traceback (most recent call last):
  File "main.py", line 10, in <module>
    data_ingestion.main()
  File "f:\ineuron\project\chicken-disease-classification\src\chickenClassifier\pipeline\stage_01_data_ingestion.py", line 16, in main
    data_ingestion.download_file()
  File "f:\ineuron\project\chicken-disease-classification\src\chickenClassifier\components\data_ingestion.py", line 22, in download_file
    os.environ['KAGGLE_USERNAME'] = kaggle_username
  File "C:\Users\Zaban\anaconda3\envs\chicken\lib\os.py", line 680, in __setitem__
    value = self.encodevalue(value)
  File "C:\Users\Zaban\anaconda3\envs\chicken\lib\os.py", line 736, in check_str
    raise TypeError("str expected, not %s" % type(value).__name__)
TypeError: str expected, not NoneType
[2023-06-09 02:03:00,701: INFO: main: >>>>>>> stage Data Ingestion stage started<<<<<]
[2023-06-09 02:03:00,734: INFO: common: yaml file:config\config.yaml loaded successfully]
[2023-06-09 02:03:00,737: INFO: common: yaml file:params.yaml loaded successfully]
[2023-06-09 02:03:00,738: INFO: common: created directory at: artifacts]
[2023-06-09 02:03:00,741: INFO: common: created directory at: artifacts/data_ingestion]
[2023-06-09 02:03:00,744: ERROR: main: str expected, not NoneType]
Traceback (most recent call last):
  File "main.py", line 10, in <module>
    data_ingestion.main()
  File "f:\ineuron\project\chicken-disease-classification\src\chickenClassifier\pipeline\stage_01_data_ingestion.py", line 16, in main
    data_ingestion.download_file()
  File "f:\ineuron\project\chicken-disease-classification\src\chickenClassifier\components\data_ingestion.py", line 23, in download_file
    os.environ['KAGGLE_USERNAME'] = kaggle_username
  File "C:\Users\Zaban\anaconda3\envs\chicken\lib\os.py", line 680, in __setitem__
    value = self.encodevalue(value)
  File "C:\Users\Zaban\anaconda3\envs\chicken\lib\os.py", line 736, in check_str
    raise TypeError("str expected, not %s" % type(value).__name__)
TypeError: str expected, not NoneType
[2023-06-09 02:04:13,779: INFO: main: >>>>>>> stage Data Ingestion stage started<<<<<]
[2023-06-09 02:04:13,783: INFO: common: yaml file:config\config.yaml loaded successfully]
[2023-06-09 02:04:13,786: INFO: common: yaml file:params.yaml loaded successfully]
[2023-06-09 02:04:13,789: INFO: common: created directory at: artifacts]
[2023-06-09 02:04:13,795: INFO: common: created directory at: artifacts/data_ingestion]
[2023-06-09 02:04:13,807: ERROR: main: str expected, not NoneType]
Traceback (most recent call last):
  File "main.py", line 10, in <module>
    data_ingestion.main()
  File "f:\ineuron\project\chicken-disease-classification\src\chickenClassifier\pipeline\stage_01_data_ingestion.py", line 16, in main
    data_ingestion.download_file()
  File "f:\ineuron\project\chicken-disease-classification\src\chickenClassifier\components\data_ingestion.py", line 23, in download_file
    os.environ['KAGGLE_USERNAME'] = kaggle_username
  File "C:\Users\Zaban\anaconda3\envs\chicken\lib\os.py", line 680, in __setitem__
    value = self.encodevalue(value)
  File "C:\Users\Zaban\anaconda3\envs\chicken\lib\os.py", line 736, in check_str
    raise TypeError("str expected, not %s" % type(value).__name__)
TypeError: str expected, not NoneType
[2023-06-09 02:04:29,974: INFO: main: >>>>>>> stage Data Ingestion stage started<<<<<]
[2023-06-09 02:04:29,984: INFO: common: yaml file:config\config.yaml loaded successfully]
[2023-06-09 02:04:29,985: INFO: common: yaml file:params.yaml loaded successfully]
[2023-06-09 02:04:29,985: INFO: common: created directory at: artifacts]
[2023-06-09 02:04:29,986: INFO: common: created directory at: artifacts/data_ingestion]
[2023-06-09 02:04:29,987: ERROR: main: str expected, not NoneType]
Traceback (most recent call last):
  File "main.py", line 10, in <module>
    data_ingestion.main()
  File "f:\ineuron\project\chicken-disease-classification\src\chickenClassifier\pipeline\stage_01_data_ingestion.py", line 16, in main
    data_ingestion.download_file()
  File "f:\ineuron\project\chicken-disease-classification\src\chickenClassifier\components\data_ingestion.py", line 23, in download_file
    os.environ['KAGGLE_USERNAME'] = kaggle_username
  File "C:\Users\Zaban\anaconda3\envs\chicken\lib\os.py", line 680, in __setitem__
    value = self.encodevalue(value)
  File "C:\Users\Zaban\anaconda3\envs\chicken\lib\os.py", line 736, in check_str
    raise TypeError("str expected, not %s" % type(value).__name__)
TypeError: str expected, not NoneType
[2023-06-09 02:09:05,076: INFO: main: >>>>>>> stage Data Ingestion stage started<<<<<]
[2023-06-09 02:09:05,081: INFO: common: yaml file:config\config.yaml loaded successfully]
[2023-06-09 02:09:05,084: INFO: common: yaml file:params.yaml loaded successfully]
[2023-06-09 02:09:05,102: INFO: common: created directory at: artifacts]
[2023-06-09 02:09:05,109: INFO: common: created directory at: artifacts/data_ingestion]
[2023-06-09 02:09:05,157: ERROR: main: str expected, not NoneType]
Traceback (most recent call last):
  File "main.py", line 10, in <module>
    data_ingestion.main()
  File "f:\ineuron\project\chicken-disease-classification\src\chickenClassifier\pipeline\stage_01_data_ingestion.py", line 16, in main
    data_ingestion.download_file()
  File "f:\ineuron\project\chicken-disease-classification\src\chickenClassifier\components\data_ingestion.py", line 23, in download_file
    os.environ['KAGGLE_USERNAME'] = kaggle_username
  File "C:\Users\Zaban\anaconda3\envs\chicken\lib\os.py", line 680, in __setitem__
    value = self.encodevalue(value)
  File "C:\Users\Zaban\anaconda3\envs\chicken\lib\os.py", line 736, in check_str
    raise TypeError("str expected, not %s" % type(value).__name__)
TypeError: str expected, not NoneType
[2023-06-09 02:09:22,729: INFO: main: >>>>>>> stage Data Ingestion stage started<<<<<]
[2023-06-09 02:09:22,734: INFO: common: yaml file:config\config.yaml loaded successfully]
[2023-06-09 02:09:22,737: INFO: common: yaml file:params.yaml loaded successfully]
[2023-06-09 02:09:22,738: INFO: common: created directory at: artifacts]
[2023-06-09 02:09:22,740: INFO: common: created directory at: artifacts/data_ingestion]
[2023-06-09 02:09:22,763: ERROR: main: name 'load_dotenv' is not defined]
Traceback (most recent call last):
  File "main.py", line 10, in <module>
    data_ingestion.main()
  File "f:\ineuron\project\chicken-disease-classification\src\chickenClassifier\pipeline\stage_01_data_ingestion.py", line 15, in main
    data_ingestion = DataIngestion(config=data_ingestion_config)
  File "f:\ineuron\project\chicken-disease-classification\src\chickenClassifier\components\data_ingestion.py", line 15, in __init__
    load_dotenv()
NameError: name 'load_dotenv' is not defined
[2023-06-09 02:09:40,049: INFO: main: >>>>>>> stage Data Ingestion stage started<<<<<]
[2023-06-09 02:09:40,056: INFO: common: yaml file:config\config.yaml loaded successfully]
[2023-06-09 02:09:40,059: INFO: common: yaml file:params.yaml loaded successfully]
[2023-06-09 02:09:40,080: INFO: common: created directory at: artifacts]
[2023-06-09 02:09:40,103: INFO: common: created directory at: artifacts/data_ingestion]
[2023-06-09 02:09:40,431: ERROR: main: name 'api' is not defined]
Traceback (most recent call last):
  File "main.py", line 10, in <module>
    data_ingestion.main()
  File "f:\ineuron\project\chicken-disease-classification\src\chickenClassifier\pipeline\stage_01_data_ingestion.py", line 16, in main
    data_ingestion.download_file()
  File "f:\ineuron\project\chicken-disease-classification\src\chickenClassifier\components\data_ingestion.py", line 28, in download_file
    api.authenticate()
NameError: name 'api' is not defined
[2023-06-09 02:10:45,425: INFO: main: >>>>>>> stage Data Ingestion stage started<<<<<]
[2023-06-09 02:10:45,434: INFO: common: yaml file:config\config.yaml loaded successfully]
[2023-06-09 02:10:45,476: INFO: common: yaml file:params.yaml loaded successfully]
[2023-06-09 02:10:45,481: INFO: common: created directory at: artifacts]
[2023-06-09 02:10:45,482: INFO: common: created directory at: artifacts/data_ingestion]
[2023-06-09 02:12:31,273: INFO: data_ingestion:  download data with kaggle!]
[2023-06-09 02:12:31,320: ERROR: main: 'DataIngestionConfig' object has no attribute 'unzip_dir']
Traceback (most recent call last):
  File "main.py", line 10, in <module>
    data_ingestion.main()
  File "f:\ineuron\project\chicken-disease-classification\src\chickenClassifier\pipeline\stage_01_data_ingestion.py", line 17, in main
    data_ingestion.extract_zip_file()
  File "f:\ineuron\project\chicken-disease-classification\src\chickenClassifier\components\data_ingestion.py", line 36, in extract_zip_file
AttributeError: 'DataIngestionConfig' object has no attribute 'unzip_dir'
[2023-06-09 02:18:01,211: INFO: main: >>>>>>> stage Data Ingestion stage started<<<<<]
[2023-06-09 02:18:01,215: INFO: common: yaml file:config\config.yaml loaded successfully]
[2023-06-09 02:18:01,217: INFO: common: yaml file:params.yaml loaded successfully]
[2023-06-09 02:18:01,227: INFO: common: created directory at: artifacts]
[2023-06-09 02:18:01,238: INFO: common: created directory at: artifacts/data_ingestion]
[2023-06-09 02:18:01,264: INFO: data_ingestion: File already exists of size: ~0 KB]
[2023-06-09 02:18:01,477: ERROR: main: 'DataIngestion' object has no attribute 'source_directory']
Traceback (most recent call last):
  File "main.py", line 10, in <module>
    data_ingestion.main()
  File "f:\ineuron\project\chicken-disease-classification\src\chickenClassifier\pipeline\stage_01_data_ingestion.py", line 17, in main
    data_ingestion.saparate_files()
  File "f:\ineuron\project\chicken-disease-classification\src\chickenClassifier\components\data_ingestion.py", line 45, in saparate_files
    source_file_path = os.path.join(self.source_directory, filename)
AttributeError: 'DataIngestion' object has no attribute 'source_directory'
[2023-06-09 02:18:38,103: INFO: main: >>>>>>> stage Data Ingestion stage started<<<<<]
[2023-06-09 02:18:38,110: INFO: common: yaml file:config\config.yaml loaded successfully]
[2023-06-09 02:18:38,130: INFO: common: yaml file:params.yaml loaded successfully]
[2023-06-09 02:18:38,134: INFO: common: created directory at: artifacts]
[2023-06-09 02:18:38,155: INFO: common: created directory at: artifacts/data_ingestion]
[2023-06-09 02:18:38,184: INFO: data_ingestion: File already exists of size: ~0 KB]
[2023-06-09 02:18:38,313: ERROR: main: name 'shutil' is not defined]
Traceback (most recent call last):
  File "main.py", line 10, in <module>
    data_ingestion.main()
  File "f:\ineuron\project\chicken-disease-classification\src\chickenClassifier\pipeline\stage_01_data_ingestion.py", line 17, in main
    data_ingestion.saparate_files()
  File "f:\ineuron\project\chicken-disease-classification\src\chickenClassifier\components\data_ingestion.py", line 47, in saparate_files
    shutil.move(source_file_path, destination_file_path)
NameError: name 'shutil' is not defined
[2023-06-09 02:21:07,527: INFO: main: >>>>>>> stage Data Ingestion stage started<<<<<]
[2023-06-09 02:21:07,533: INFO: common: yaml file:config\config.yaml loaded successfully]
[2023-06-09 02:21:07,536: INFO: common: yaml file:params.yaml loaded successfully]
[2023-06-09 02:21:07,548: INFO: common: created directory at: artifacts]
[2023-06-09 02:21:07,554: INFO: common: created directory at: artifacts/data_ingestion]
[2023-06-09 02:21:07,581: INFO: data_ingestion: File already exists of size: ~0 KB]
[2023-06-09 02:21:27,627: INFO: main: <<<<<<stage Data Ingestion stage completed >>>>>>>>>>

x==============x]
[2023-06-10 10:05:28,860: INFO: main: >>>>>>> stage Data Ingestion stage started<<<<<]
[2023-06-10 10:05:28,970: INFO: common: yaml file:config\config.yaml loaded successfully]
[2023-06-10 10:05:29,008: INFO: common: yaml file:params.yaml loaded successfully]
[2023-06-10 10:05:29,011: INFO: common: created directory at: artifacts]
[2023-06-10 10:05:29,013: INFO: common: created directory at: artifacts/data_ingestion]
[2023-06-10 10:05:29,062: INFO: data_ingestion: File already exists of size: ~0 KB]
[2023-06-10 10:05:29,063: INFO: main: <<<<<<stage Data Ingestion stage completed >>>>>>>>>>

x==============x]
[2023-06-10 10:05:29,102: INFO: main: >>>>>>> stage Prepare Base Model started<<<<<]
[2023-06-10 10:05:29,112: INFO: common: yaml file:config\config.yaml loaded successfully]
[2023-06-10 10:05:29,148: INFO: common: yaml file:params.yaml loaded successfully]
[2023-06-10 10:05:29,150: INFO: common: created directory at: artifacts]
[2023-06-10 10:05:29,152: ERROR: main: "'ConfigBox' object has no attribute 'prepare_base_model_config'"]
Traceback (most recent call last):
  File "box\box.py", line 503, in box.box.Box.__getitem__
KeyError: 'prepare_base_model_config'

The above exception was the direct cause of the following exception:

Traceback (most recent call last):
  File "box\box.py", line 536, in box.box.Box.__getattr__
  File "box\box.py", line 524, in box.box.Box.__getitem__
box.exceptions.BoxKeyError: "'prepare_base_model_config'"

During handling of the above exception, another exception occurred:

Traceback (most recent call last):
  File "box\box.py", line 538, in box.box.Box.__getattr__
AttributeError: 'ConfigBox' object has no attribute 'prepare_base_model_config'

The above exception was the direct cause of the following exception:

Traceback (most recent call last):
  File "box\config_box.py", line 28, in box.config_box.ConfigBox.__getattr__
  File "box\box.py", line 552, in box.box.Box.__getattr__
box.exceptions.BoxKeyError: "'ConfigBox' object has no attribute 'prepare_base_model_config'"

During handling of the above exception, another exception occurred:

Traceback (most recent call last):
  File "box\box.py", line 503, in box.box.Box.__getitem__
KeyError: 'prepare_base_model_config'

The above exception was the direct cause of the following exception:

Traceback (most recent call last):
  File "box\box.py", line 536, in box.box.Box.__getattr__
  File "box\box.py", line 524, in box.box.Box.__getitem__
box.exceptions.BoxKeyError: "'prepare_base_model_config'"

During handling of the above exception, another exception occurred:

Traceback (most recent call last):
  File "box\box.py", line 538, in box.box.Box.__getattr__
AttributeError: 'ConfigBox' object has no attribute 'prepare_base_model_config'

The above exception was the direct cause of the following exception:

Traceback (most recent call last):
  File "main.py", line 22, in <module>
    data_ingestion.main()
  File "f:\ineuron\project\chicken-disease-classification\src\chickenClassifier\pipeline\stage_02_prepare_base_model.py", line 13, in main
    prepare_base_model_config = config.get_prepare_base_model_config()
  File "f:\ineuron\project\chicken-disease-classification\src\chickenClassifier\config\configuration.py", line 30, in get_prepare_base_model_config
    config = self.config.prepare_base_model_config
  File "box\config_box.py", line 30, in box.config_box.ConfigBox.__getattr__
  File "box\box.py", line 552, in box.box.Box.__getattr__
box.exceptions.BoxKeyError: "'ConfigBox' object has no attribute 'prepare_base_model_config'"
[2023-06-10 10:35:40,437: INFO: main: >>>>>>> stage Data Ingestion stage started<<<<<]
[2023-06-10 10:35:40,536: INFO: common: yaml file:config\config.yaml loaded successfully]
[2023-06-10 10:35:40,541: INFO: common: yaml file:params.yaml loaded successfully]
[2023-06-10 10:35:40,543: INFO: common: created directory at: artifacts]
[2023-06-10 10:35:40,544: INFO: common: created directory at: artifacts/data_ingestion]
[2023-06-10 10:35:40,574: INFO: data_ingestion: File already exists of size: ~0 KB]
[2023-06-10 10:35:40,575: INFO: main: <<<<<<stage Data Ingestion stage completed >>>>>>>>>>

x==============x]
[2023-06-10 10:35:40,578: INFO: main: >>>>>>> stage Prepare Base Model started<<<<<]
[2023-06-10 10:35:40,621: INFO: common: yaml file:config\config.yaml loaded successfully]
[2023-06-10 10:35:40,630: INFO: common: yaml file:params.yaml loaded successfully]
[2023-06-10 10:35:40,631: INFO: common: created directory at: artifacts]
[2023-06-10 10:35:40,661: INFO: common: created directory at: artifacts/prepare_base_model]
[2023-06-10 10:35:40,666: ERROR: main: module 'keras.api._v2.keras' has no attribute 'application']
Traceback (most recent call last):
  File "main.py", line 22, in <module>
    data_ingestion.main()
  File "f:\ineuron\project\chicken-disease-classification\src\chickenClassifier\pipeline\stage_02_prepare_base_model.py", line 15, in main
    prepare_base_model.get_base_model()
  File "f:\ineuron\project\chicken-disease-classification\src\chickenClassifier\components\prepare_base_model.py", line 14, in get_base_model
    self.model = tf.keras.application.vgg16.VGG16(
AttributeError: module 'keras.api._v2.keras' has no attribute 'application'
[2023-06-10 10:36:20,417: INFO: main: >>>>>>> stage Data Ingestion stage started<<<<<]
[2023-06-10 10:36:20,420: INFO: common: yaml file:config\config.yaml loaded successfully]
[2023-06-10 10:36:20,423: INFO: common: yaml file:params.yaml loaded successfully]
[2023-06-10 10:36:20,425: INFO: common: created directory at: artifacts]
[2023-06-10 10:36:20,426: INFO: common: created directory at: artifacts/data_ingestion]
[2023-06-10 10:36:20,451: INFO: data_ingestion: File already exists of size: ~0 KB]
[2023-06-10 10:36:20,452: INFO: main: <<<<<<stage Data Ingestion stage completed >>>>>>>>>>

x==============x]
[2023-06-10 10:36:20,453: INFO: main: >>>>>>> stage Prepare Base Model started<<<<<]
[2023-06-10 10:36:20,460: INFO: common: yaml file:config\config.yaml loaded successfully]
[2023-06-10 10:36:20,540: INFO: common: yaml file:params.yaml loaded successfully]
[2023-06-10 10:36:20,548: INFO: common: created directory at: artifacts]
[2023-06-10 10:36:20,550: INFO: common: created directory at: artifacts/prepare_base_model]
[2023-06-10 10:36:20,551: ERROR: main: VGG16() got an unexpected keyword argument 'includ_top']
Traceback (most recent call last):
  File "main.py", line 22, in <module>
    data_ingestion.main()
  File "f:\ineuron\project\chicken-disease-classification\src\chickenClassifier\pipeline\stage_02_prepare_base_model.py", line 15, in main
    prepare_base_model.get_base_model()
  File "f:\ineuron\project\chicken-disease-classification\src\chickenClassifier\components\prepare_base_model.py", line 14, in get_base_model
    self.model = tf.keras.applications.vgg16.VGG16(
TypeError: VGG16() got an unexpected keyword argument 'includ_top'
[2023-06-10 10:36:45,693: INFO: main: >>>>>>> stage Data Ingestion stage started<<<<<]
[2023-06-10 10:36:45,699: INFO: common: yaml file:config\config.yaml loaded successfully]
[2023-06-10 10:36:45,702: INFO: common: yaml file:params.yaml loaded successfully]
[2023-06-10 10:36:45,704: INFO: common: created directory at: artifacts]
[2023-06-10 10:36:45,704: INFO: common: created directory at: artifacts/data_ingestion]
[2023-06-10 10:36:45,731: INFO: data_ingestion: File already exists of size: ~0 KB]
[2023-06-10 10:36:45,765: INFO: main: <<<<<<stage Data Ingestion stage completed >>>>>>>>>>

x==============x]
[2023-06-10 10:36:45,767: INFO: main: >>>>>>> stage Prepare Base Model started<<<<<]
[2023-06-10 10:36:45,813: INFO: common: yaml file:config\config.yaml loaded successfully]
[2023-06-10 10:36:45,824: INFO: common: yaml file:params.yaml loaded successfully]
[2023-06-10 10:36:45,856: INFO: common: created directory at: artifacts]
[2023-06-10 10:36:45,901: INFO: common: created directory at: artifacts/prepare_base_model]
[2023-06-10 10:37:02,482: WARNING: saving_utils: Compiled the loaded model, but the compiled metrics have yet to be built. `model.compile_metrics` will be empty until you train or evaluate the model.]
[2023-06-10 10:37:03,842: ERROR: main: ('Keyword argument not understood:', 'output')]
Traceback (most recent call last):
  File "main.py", line 22, in <module>
    data_ingestion.main()
  File "f:\ineuron\project\chicken-disease-classification\src\chickenClassifier\pipeline\stage_02_prepare_base_model.py", line 16, in main
    prepare_base_model.update_base_model()
  File "f:\ineuron\project\chicken-disease-classification\src\chickenClassifier\components\prepare_base_model.py", line 54, in update_base_model
    self.full_model = self._prepare_full_model(
  File "f:\ineuron\project\chicken-disease-classification\src\chickenClassifier\components\prepare_base_model.py", line 37, in _prepare_full_model
    full_model = tf.keras.models.Model(
  File "C:\Users\Zaban\anaconda3\envs\chicken\lib\site-packages\tensorflow\python\trackable\base.py", line 205, in _method_wrapper
    result = method(self, *args, **kwargs)
  File "C:\Users\Zaban\anaconda3\envs\chicken\lib\site-packages\keras\utils\traceback_utils.py", line 70, in error_handler
    raise e.with_traceback(filtered_tb) from None
  File "C:\Users\Zaban\anaconda3\envs\chicken\lib\site-packages\keras\utils\generic_utils.py", line 514, in validate_kwargs
    raise TypeError(error_message, kwarg)
TypeError: ('Keyword argument not understood:', 'output')
[2023-06-10 10:39:33,586: INFO: main: >>>>>>> stage Data Ingestion stage started<<<<<]
[2023-06-10 10:39:33,589: INFO: common: yaml file:config\config.yaml loaded successfully]
[2023-06-10 10:39:33,594: INFO: common: yaml file:params.yaml loaded successfully]
[2023-06-10 10:39:33,595: INFO: common: created directory at: artifacts]
[2023-06-10 10:39:33,596: INFO: common: created directory at: artifacts/data_ingestion]
[2023-06-10 10:39:33,599: INFO: data_ingestion: File already exists of size: ~0 KB]
[2023-06-10 10:39:33,600: INFO: main: <<<<<<stage Data Ingestion stage completed >>>>>>>>>>

x==============x]
[2023-06-10 10:39:33,629: INFO: main: >>>>>>> stage Prepare Base Model started<<<<<]
[2023-06-10 10:39:33,639: INFO: common: yaml file:config\config.yaml loaded successfully]
[2023-06-10 10:39:33,677: INFO: common: yaml file:params.yaml loaded successfully]
[2023-06-10 10:39:33,679: INFO: common: created directory at: artifacts]
[2023-06-10 10:39:33,683: INFO: common: created directory at: artifacts/prepare_base_model]
[2023-06-10 10:39:34,503: WARNING: saving_utils: Compiled the loaded model, but the compiled metrics have yet to be built. `model.compile_metrics` will be empty until you train or evaluate the model.]
[2023-06-10 10:39:37,615: INFO: main: <<<<<<stage Prepare Base Model completed >>>>>>>>>>

x==============x]
[2023-06-13 18:30:37,533: INFO: main: >>>>>>> stage Data Ingestion stage started<<<<<]
[2023-06-13 18:30:37,659: INFO: common: yaml file:config\config.yaml loaded successfully]
[2023-06-13 18:30:37,711: INFO: common: yaml file:params.yaml loaded successfully]
[2023-06-13 18:30:37,714: INFO: common: created directory at: artifacts]
[2023-06-13 18:30:37,715: INFO: common: created directory at: artifacts/data_ingestion]
[2023-06-13 18:30:37,718: INFO: data_ingestion: File already exists of size: ~0 KB]
[2023-06-13 18:30:37,719: INFO: main: <<<<<<stage Data Ingestion stage completed >>>>>>>>>>

x==============x]
[2023-06-13 18:30:37,720: INFO: main: >>>>>>> stage Prepare Base Model started<<<<<]
[2023-06-13 18:30:37,726: INFO: common: yaml file:config\config.yaml loaded successfully]
[2023-06-13 18:30:37,730: INFO: common: yaml file:params.yaml loaded successfully]
[2023-06-13 18:30:37,731: INFO: common: created directory at: artifacts]
[2023-06-13 18:30:37,732: INFO: common: created directory at: artifacts/prepare_base_model]
[2023-06-13 18:30:38,906: WARNING: saving_utils: Compiled the loaded model, but the compiled metrics have yet to be built. `model.compile_metrics` will be empty until you train or evaluate the model.]
[2023-06-13 18:30:42,321: INFO: main: <<<<<<stage Prepare Base Model completed >>>>>>>>>>

x==============x]
[2023-06-13 18:30:42,322: INFO: main: **********************]
[2023-06-13 18:30:42,322: INFO: main: >>>>>>>>stage Training started <<<<<<<<<<]
[2023-06-13 18:30:42,323: ERROR: main: name 'obj' is not defined]
Traceback (most recent call last):
  File "main.py", line 35, in <module>
    obj.ModelTrainingPipeline()
NameError: name 'obj' is not defined
[2023-06-13 18:31:14,898: INFO: main: >>>>>>> stage Data Ingestion stage started<<<<<]
[2023-06-13 18:31:14,911: INFO: common: yaml file:config\config.yaml loaded successfully]
[2023-06-13 18:31:14,942: INFO: common: yaml file:params.yaml loaded successfully]
[2023-06-13 18:31:14,946: INFO: common: created directory at: artifacts]
[2023-06-13 18:31:14,948: INFO: common: created directory at: artifacts/data_ingestion]
[2023-06-13 18:31:15,002: INFO: data_ingestion: File already exists of size: ~0 KB]
[2023-06-13 18:31:15,043: INFO: main: <<<<<<stage Data Ingestion stage completed >>>>>>>>>>

x==============x]
[2023-06-13 18:31:15,055: INFO: main: >>>>>>> stage Prepare Base Model started<<<<<]
[2023-06-13 18:31:15,104: INFO: common: yaml file:config\config.yaml loaded successfully]
[2023-06-13 18:31:15,148: INFO: common: yaml file:params.yaml loaded successfully]
[2023-06-13 18:31:15,185: INFO: common: created directory at: artifacts]
[2023-06-13 18:31:15,202: INFO: common: created directory at: artifacts/prepare_base_model]
[2023-06-13 18:31:16,269: WARNING: saving_utils: Compiled the loaded model, but the compiled metrics have yet to be built. `model.compile_metrics` will be empty until you train or evaluate the model.]
[2023-06-13 18:31:19,444: INFO: main: <<<<<<stage Prepare Base Model completed >>>>>>>>>>

x==============x]
[2023-06-13 18:31:19,445: INFO: main: **********************]
[2023-06-13 18:31:19,446: INFO: main: >>>>>>>>stage Training started <<<<<<<<<<]
[2023-06-13 18:31:19,446: ERROR: main: name 'obj' is not defined]
Traceback (most recent call last):
  File "main.py", line 35, in <module>
    obj.TrainingPipeline()
NameError: name 'obj' is not defined
[2023-06-13 18:31:50,718: INFO: main: >>>>>>> stage Data Ingestion stage started<<<<<]
[2023-06-13 18:31:50,731: INFO: common: yaml file:config\config.yaml loaded successfully]
[2023-06-13 18:31:50,761: INFO: common: yaml file:params.yaml loaded successfully]
[2023-06-13 18:31:50,763: INFO: common: created directory at: artifacts]
[2023-06-13 18:31:50,764: INFO: common: created directory at: artifacts/data_ingestion]
[2023-06-13 18:31:50,771: INFO: data_ingestion: File already exists of size: ~0 KB]
[2023-06-13 18:31:50,782: INFO: main: <<<<<<stage Data Ingestion stage completed >>>>>>>>>>

x==============x]
[2023-06-13 18:31:50,803: INFO: main: >>>>>>> stage Prepare Base Model started<<<<<]
[2023-06-13 18:31:50,857: INFO: common: yaml file:config\config.yaml loaded successfully]
[2023-06-13 18:31:50,894: INFO: common: yaml file:params.yaml loaded successfully]
[2023-06-13 18:31:50,896: INFO: common: created directory at: artifacts]
[2023-06-13 18:31:50,899: INFO: common: created directory at: artifacts/prepare_base_model]
[2023-06-13 18:31:51,857: WARNING: saving_utils: Compiled the loaded model, but the compiled metrics have yet to be built. `model.compile_metrics` will be empty until you train or evaluate the model.]
[2023-06-13 18:31:55,035: INFO: main: <<<<<<stage Prepare Base Model completed >>>>>>>>>>

x==============x]
[2023-06-13 18:31:55,036: INFO: main: **********************]
[2023-06-13 18:31:55,036: INFO: main: >>>>>>>>stage Training started <<<<<<<<<<]
[2023-06-13 18:31:55,042: INFO: common: yaml file:config\config.yaml loaded successfully]
[2023-06-13 18:31:55,047: INFO: common: yaml file:params.yaml loaded successfully]
[2023-06-13 18:31:55,060: INFO: common: created directory at: artifacts]
[2023-06-13 18:31:55,073: ERROR: main: "'ConfigBox' object has no attribute 'checkpoint_model_filepath'"]
Traceback (most recent call last):
  File "box\box.py", line 503, in box.box.Box.__getitem__
KeyError: 'checkpoint_model_filepath'

The above exception was the direct cause of the following exception:

Traceback (most recent call last):
  File "box\box.py", line 536, in box.box.Box.__getattr__
  File "box\box.py", line 524, in box.box.Box.__getitem__
box.exceptions.BoxKeyError: "'checkpoint_model_filepath'"

During handling of the above exception, another exception occurred:

Traceback (most recent call last):
  File "box\box.py", line 538, in box.box.Box.__getattr__
AttributeError: 'ConfigBox' object has no attribute 'checkpoint_model_filepath'

The above exception was the direct cause of the following exception:

Traceback (most recent call last):
  File "box\config_box.py", line 28, in box.config_box.ConfigBox.__getattr__
  File "box\box.py", line 552, in box.box.Box.__getattr__
box.exceptions.BoxKeyError: "'ConfigBox' object has no attribute 'checkpoint_model_filepath'"

During handling of the above exception, another exception occurred:

Traceback (most recent call last):
  File "box\box.py", line 503, in box.box.Box.__getitem__
KeyError: 'checkpoint_model_filepath'

The above exception was the direct cause of the following exception:

Traceback (most recent call last):
  File "box\box.py", line 536, in box.box.Box.__getattr__
  File "box\box.py", line 524, in box.box.Box.__getitem__
box.exceptions.BoxKeyError: "'checkpoint_model_filepath'"

During handling of the above exception, another exception occurred:

Traceback (most recent call last):
  File "box\box.py", line 538, in box.box.Box.__getattr__
AttributeError: 'ConfigBox' object has no attribute 'checkpoint_model_filepath'

The above exception was the direct cause of the following exception:

Traceback (most recent call last):
  File "main.py", line 36, in <module>
    obj.main()
  File "f:\ineuron\project\chicken-disease-classification\src\chickenClassifier\pipeline\stage_03_training.py", line 15, in main
    callback_config = config.get_callback_config()
  File "f:\ineuron\project\chicken-disease-classification\src\chickenClassifier\config\configuration.py", line 52, in get_callback_config
    model_ckpt_dir = os.path.dirname(config.checkpoint_model_filepath)
  File "box\config_box.py", line 30, in box.config_box.ConfigBox.__getattr__
  File "box\box.py", line 552, in box.box.Box.__getattr__
box.exceptions.BoxKeyError: "'ConfigBox' object has no attribute 'checkpoint_model_filepath'"
[2023-06-13 18:34:53,874: INFO: main: >>>>>>> stage Data Ingestion stage started<<<<<]
[2023-06-13 18:34:53,882: INFO: common: yaml file:config\config.yaml loaded successfully]
[2023-06-13 18:34:53,886: INFO: common: yaml file:params.yaml loaded successfully]
[2023-06-13 18:34:53,911: INFO: common: created directory at: artifacts]
[2023-06-13 18:34:53,920: INFO: common: created directory at: artifacts/data_ingestion]
[2023-06-13 18:34:53,929: INFO: data_ingestion: File already exists of size: ~0 KB]
[2023-06-13 18:34:53,932: INFO: main: <<<<<<stage Data Ingestion stage completed >>>>>>>>>>

x==============x]
[2023-06-13 18:34:53,935: INFO: main: >>>>>>> stage Prepare Base Model started<<<<<]
[2023-06-13 18:34:53,984: INFO: common: yaml file:config\config.yaml loaded successfully]
[2023-06-13 18:34:54,031: INFO: common: yaml file:params.yaml loaded successfully]
[2023-06-13 18:34:54,036: INFO: common: created directory at: artifacts]
[2023-06-13 18:34:54,039: INFO: common: created directory at: artifacts/prepare_base_model]
[2023-06-13 18:34:54,981: WARNING: saving_utils: Compiled the loaded model, but the compiled metrics have yet to be built. `model.compile_metrics` will be empty until you train or evaluate the model.]
[2023-06-13 18:34:58,551: INFO: main: <<<<<<stage Prepare Base Model completed >>>>>>>>>>

x==============x]
[2023-06-13 18:34:58,552: INFO: main: **********************]
[2023-06-13 18:34:58,552: INFO: main: >>>>>>>>stage Training started <<<<<<<<<<]
[2023-06-13 18:34:58,558: INFO: common: yaml file:config\config.yaml loaded successfully]
[2023-06-13 18:34:58,562: INFO: common: yaml file:params.yaml loaded successfully]
[2023-06-13 18:34:58,586: INFO: common: created directory at: artifacts]
[2023-06-13 18:34:58,590: INFO: common: created directory at: artifacts\callbacks\checkpoint_dir]
[2023-06-13 18:34:58,593: INFO: common: created directory at: artifacts\callbacks\tensorboard_log_dir]
[2023-06-13 18:34:58,623: ERROR: main: "'ConfigBox' object has no attribute 'ckeckpoint_model_filepath'"]
Traceback (most recent call last):
  File "box\box.py", line 503, in box.box.Box.__getitem__
KeyError: 'ckeckpoint_model_filepath'

The above exception was the direct cause of the following exception:

Traceback (most recent call last):
  File "box\box.py", line 536, in box.box.Box.__getattr__
  File "box\box.py", line 524, in box.box.Box.__getitem__
box.exceptions.BoxKeyError: "'ckeckpoint_model_filepath'"

During handling of the above exception, another exception occurred:

Traceback (most recent call last):
  File "box\box.py", line 538, in box.box.Box.__getattr__
AttributeError: 'ConfigBox' object has no attribute 'ckeckpoint_model_filepath'

The above exception was the direct cause of the following exception:

Traceback (most recent call last):
  File "box\config_box.py", line 28, in box.config_box.ConfigBox.__getattr__
  File "box\box.py", line 552, in box.box.Box.__getattr__
box.exceptions.BoxKeyError: "'ConfigBox' object has no attribute 'ckeckpoint_model_filepath'"

During handling of the above exception, another exception occurred:

Traceback (most recent call last):
  File "box\box.py", line 503, in box.box.Box.__getitem__
KeyError: 'ckeckpoint_model_filepath'

The above exception was the direct cause of the following exception:

Traceback (most recent call last):
  File "box\box.py", line 536, in box.box.Box.__getattr__
  File "box\box.py", line 524, in box.box.Box.__getitem__
box.exceptions.BoxKeyError: "'ckeckpoint_model_filepath'"

During handling of the above exception, another exception occurred:

Traceback (most recent call last):
  File "box\box.py", line 538, in box.box.Box.__getattr__
AttributeError: 'ConfigBox' object has no attribute 'ckeckpoint_model_filepath'

The above exception was the direct cause of the following exception:

Traceback (most recent call last):
  File "main.py", line 36, in <module>
    model_trainer.main()
  File "f:\ineuron\project\chicken-disease-classification\src\chickenClassifier\pipeline\stage_03_training.py", line 15, in main
    callback_config = config.get_callback_config()
  File "f:\ineuron\project\chicken-disease-classification\src\chickenClassifier\config\configuration.py", line 60, in get_callback_config
    checkpoint_model_filepath = Path(config.ckeckpoint_model_filepath)
  File "box\config_box.py", line 30, in box.config_box.ConfigBox.__getattr__
  File "box\box.py", line 552, in box.box.Box.__getattr__
box.exceptions.BoxKeyError: "'ConfigBox' object has no attribute 'ckeckpoint_model_filepath'"
[2023-06-13 18:35:45,398: INFO: main: >>>>>>> stage Data Ingestion stage started<<<<<]
[2023-06-13 18:35:45,405: INFO: common: yaml file:config\config.yaml loaded successfully]
[2023-06-13 18:35:45,410: INFO: common: yaml file:params.yaml loaded successfully]
[2023-06-13 18:35:45,411: INFO: common: created directory at: artifacts]
[2023-06-13 18:35:45,412: INFO: common: created directory at: artifacts/data_ingestion]
[2023-06-13 18:35:45,450: INFO: data_ingestion: File already exists of size: ~0 KB]
[2023-06-13 18:35:45,453: INFO: main: <<<<<<stage Data Ingestion stage completed >>>>>>>>>>

x==============x]
[2023-06-13 18:35:45,455: INFO: main: >>>>>>> stage Prepare Base Model started<<<<<]
[2023-06-13 18:35:45,504: INFO: common: yaml file:config\config.yaml loaded successfully]
[2023-06-13 18:35:45,520: INFO: common: yaml file:params.yaml loaded successfully]
[2023-06-13 18:35:45,552: INFO: common: created directory at: artifacts]
[2023-06-13 18:35:45,554: INFO: common: created directory at: artifacts/prepare_base_model]
[2023-06-13 18:35:46,506: WARNING: saving_utils: Compiled the loaded model, but the compiled metrics have yet to be built. `model.compile_metrics` will be empty until you train or evaluate the model.]
[2023-06-13 18:35:50,258: INFO: main: <<<<<<stage Prepare Base Model completed >>>>>>>>>>

x==============x]
[2023-06-13 18:35:50,259: INFO: main: **********************]
[2023-06-13 18:35:50,260: INFO: main: >>>>>>>>stage Training started <<<<<<<<<<]
[2023-06-13 18:35:50,267: INFO: common: yaml file:config\config.yaml loaded successfully]
[2023-06-13 18:35:50,271: INFO: common: yaml file:params.yaml loaded successfully]
[2023-06-13 18:35:50,284: INFO: common: created directory at: artifacts]
[2023-06-13 18:35:50,297: INFO: common: created directory at: artifacts\callbacks\checkpoint_dir]
[2023-06-13 18:35:50,298: INFO: common: created directory at: artifacts\callbacks\tensorboard_log_dir]
[2023-06-13 18:35:50,301: ERROR: main: name 'callaback' is not defined]
Traceback (most recent call last):
  File "main.py", line 36, in <module>
    model_trainer.main()
  File "f:\ineuron\project\chicken-disease-classification\src\chickenClassifier\pipeline\stage_03_training.py", line 17, in main
    callback_list = callaback.get_tb_ckpt_callabacks()
NameError: name 'callaback' is not defined
[2023-06-13 18:37:06,464: INFO: main: >>>>>>> stage Data Ingestion stage started<<<<<]
[2023-06-13 18:37:06,480: INFO: common: yaml file:config\config.yaml loaded successfully]
[2023-06-13 18:37:06,514: INFO: common: yaml file:params.yaml loaded successfully]
[2023-06-13 18:37:06,518: INFO: common: created directory at: artifacts]
[2023-06-13 18:37:06,520: INFO: common: created directory at: artifacts/data_ingestion]
[2023-06-13 18:37:06,553: INFO: data_ingestion: File already exists of size: ~0 KB]
[2023-06-13 18:37:06,554: INFO: main: <<<<<<stage Data Ingestion stage completed >>>>>>>>>>

x==============x]
[2023-06-13 18:37:06,556: INFO: main: >>>>>>> stage Prepare Base Model started<<<<<]
[2023-06-13 18:37:06,572: INFO: common: yaml file:config\config.yaml loaded successfully]
[2023-06-13 18:37:06,578: INFO: common: yaml file:params.yaml loaded successfully]
[2023-06-13 18:37:06,582: INFO: common: created directory at: artifacts]
[2023-06-13 18:37:06,584: INFO: common: created directory at: artifacts/prepare_base_model]
[2023-06-13 18:37:07,619: WARNING: saving_utils: Compiled the loaded model, but the compiled metrics have yet to be built. `model.compile_metrics` will be empty until you train or evaluate the model.]
[2023-06-13 18:37:11,750: INFO: main: <<<<<<stage Prepare Base Model completed >>>>>>>>>>

x==============x]
[2023-06-13 18:37:11,751: INFO: main: **********************]
[2023-06-13 18:37:11,751: INFO: main: >>>>>>>>stage Training started <<<<<<<<<<]
[2023-06-13 18:37:11,756: INFO: common: yaml file:config\config.yaml loaded successfully]
[2023-06-13 18:37:11,759: INFO: common: yaml file:params.yaml loaded successfully]
[2023-06-13 18:37:11,761: INFO: common: created directory at: artifacts]
[2023-06-13 18:37:11,762: INFO: common: created directory at: artifacts\callbacks\checkpoint_dir]
[2023-06-13 18:37:11,763: INFO: common: created directory at: artifacts\callbacks\tensorboard_log_dir]
[2023-06-13 18:37:11,764: ERROR: main: 'Callback' object has no attribute 'get_tb_ckpt_callabacks']
Traceback (most recent call last):
  File "main.py", line 36, in <module>
    model_trainer.main()
  File "f:\ineuron\project\chicken-disease-classification\src\chickenClassifier\pipeline\stage_03_training.py", line 17, in main
    callback_list = callback.get_tb_ckpt_callabacks()
AttributeError: 'Callback' object has no attribute 'get_tb_ckpt_callabacks'
[2023-06-13 18:37:28,848: INFO: main: >>>>>>> stage Data Ingestion stage started<<<<<]
[2023-06-13 18:37:28,883: INFO: common: yaml file:config\config.yaml loaded successfully]
[2023-06-13 18:37:28,901: INFO: common: yaml file:params.yaml loaded successfully]
[2023-06-13 18:37:29,032: INFO: common: created directory at: artifacts]
[2023-06-13 18:37:29,084: INFO: common: created directory at: artifacts/data_ingestion]
[2023-06-13 18:37:29,089: INFO: data_ingestion: File already exists of size: ~0 KB]
[2023-06-13 18:37:29,093: INFO: main: <<<<<<stage Data Ingestion stage completed >>>>>>>>>>

x==============x]
[2023-06-13 18:37:29,094: INFO: main: >>>>>>> stage Prepare Base Model started<<<<<]
[2023-06-13 18:37:29,106: INFO: common: yaml file:config\config.yaml loaded successfully]
[2023-06-13 18:37:29,149: INFO: common: yaml file:params.yaml loaded successfully]
[2023-06-13 18:37:29,151: INFO: common: created directory at: artifacts]
[2023-06-13 18:37:29,187: INFO: common: created directory at: artifacts/prepare_base_model]
[2023-06-13 18:37:30,068: WARNING: saving_utils: Compiled the loaded model, but the compiled metrics have yet to be built. `model.compile_metrics` will be empty until you train or evaluate the model.]
[2023-06-13 18:37:33,697: INFO: main: <<<<<<stage Prepare Base Model completed >>>>>>>>>>

x==============x]
[2023-06-13 18:37:33,698: INFO: main: **********************]
[2023-06-13 18:37:33,699: INFO: main: >>>>>>>>stage Training started <<<<<<<<<<]
[2023-06-13 18:37:33,707: INFO: common: yaml file:config\config.yaml loaded successfully]
[2023-06-13 18:37:33,732: INFO: common: yaml file:params.yaml loaded successfully]
[2023-06-13 18:37:33,734: INFO: common: created directory at: artifacts]
[2023-06-13 18:37:33,735: INFO: common: created directory at: artifacts\callbacks\checkpoint_dir]
[2023-06-13 18:37:33,737: INFO: common: created directory at: artifacts\callbacks\tensorboard_log_dir]
[2023-06-13 18:37:33,749: ERROR: main: 'CallbackConfig' object has no attribute 'tenforboard_root_log_dir']
Traceback (most recent call last):
  File "main.py", line 36, in <module>
    model_trainer.main()
  File "f:\ineuron\project\chicken-disease-classification\src\chickenClassifier\pipeline\stage_03_training.py", line 17, in main
    callback_list = callback.get_tb_ckpt_callbacks()
  File "f:\ineuron\project\chicken-disease-classification\src\chickenClassifier\components\callbacks.py", line 29, in get_tb_ckpt_callbacks
    self._create_tb_callbacks,
  File "f:\ineuron\project\chicken-disease-classification\src\chickenClassifier\components\callbacks.py", line 14, in _create_tb_callbacks
    self.config.tenforboard_root_log_dir,
AttributeError: 'CallbackConfig' object has no attribute 'tenforboard_root_log_dir'
[2023-06-13 18:38:05,805: INFO: main: >>>>>>> stage Data Ingestion stage started<<<<<]
[2023-06-13 18:38:05,826: INFO: common: yaml file:config\config.yaml loaded successfully]
[2023-06-13 18:38:05,832: INFO: common: yaml file:params.yaml loaded successfully]
[2023-06-13 18:38:05,848: INFO: common: created directory at: artifacts]
[2023-06-13 18:38:05,867: INFO: common: created directory at: artifacts/data_ingestion]
[2023-06-13 18:38:05,871: INFO: data_ingestion: File already exists of size: ~0 KB]
[2023-06-13 18:38:05,873: INFO: main: <<<<<<stage Data Ingestion stage completed >>>>>>>>>>

x==============x]
[2023-06-13 18:38:05,876: INFO: main: >>>>>>> stage Prepare Base Model started<<<<<]
[2023-06-13 18:38:05,935: INFO: common: yaml file:config\config.yaml loaded successfully]
[2023-06-13 18:38:05,982: INFO: common: yaml file:params.yaml loaded successfully]
[2023-06-13 18:38:05,987: INFO: common: created directory at: artifacts]
[2023-06-13 18:38:05,989: INFO: common: created directory at: artifacts/prepare_base_model]
[2023-06-13 18:38:06,930: WARNING: saving_utils: Compiled the loaded model, but the compiled metrics have yet to be built. `model.compile_metrics` will be empty until you train or evaluate the model.]
[2023-06-13 18:38:10,094: INFO: main: <<<<<<stage Prepare Base Model completed >>>>>>>>>>

x==============x]
[2023-06-13 18:38:10,095: INFO: main: **********************]
[2023-06-13 18:38:10,096: INFO: main: >>>>>>>>stage Training started <<<<<<<<<<]
[2023-06-13 18:38:10,116: INFO: common: yaml file:config\config.yaml loaded successfully]
[2023-06-13 18:38:10,135: INFO: common: yaml file:params.yaml loaded successfully]
[2023-06-13 18:38:10,138: INFO: common: created directory at: artifacts]
[2023-06-13 18:38:10,152: INFO: common: created directory at: artifacts\callbacks\checkpoint_dir]
[2023-06-13 18:38:10,158: INFO: common: created directory at: artifacts\callbacks\tensorboard_log_dir]
[2023-06-13 18:38:10,166: ERROR: main: 'CallbackConfig' object has no attribute 'ckeckpoint_model_filepath']
Traceback (most recent call last):
  File "main.py", line 36, in <module>
    model_trainer.main()
  File "f:\ineuron\project\chicken-disease-classification\src\chickenClassifier\pipeline\stage_03_training.py", line 17, in main
    callback_list = callback.get_tb_ckpt_callbacks()
  File "f:\ineuron\project\chicken-disease-classification\src\chickenClassifier\components\callbacks.py", line 30, in get_tb_ckpt_callbacks
    self._create_ckpt_callbacks
  File "f:\ineuron\project\chicken-disease-classification\src\chickenClassifier\components\callbacks.py", line 23, in _create_ckpt_callbacks
    filepath = self.config.ckeckpoint_model_filepath,
AttributeError: 'CallbackConfig' object has no attribute 'ckeckpoint_model_filepath'
[2023-06-13 18:38:30,181: INFO: main: >>>>>>> stage Data Ingestion stage started<<<<<]
[2023-06-13 18:38:30,209: INFO: common: yaml file:config\config.yaml loaded successfully]
[2023-06-13 18:38:30,234: INFO: common: yaml file:params.yaml loaded successfully]
[2023-06-13 18:38:30,236: INFO: common: created directory at: artifacts]
[2023-06-13 18:38:30,238: INFO: common: created directory at: artifacts/data_ingestion]
[2023-06-13 18:38:30,286: INFO: data_ingestion: File already exists of size: ~0 KB]
[2023-06-13 18:38:30,290: INFO: main: <<<<<<stage Data Ingestion stage completed >>>>>>>>>>

x==============x]
[2023-06-13 18:38:30,293: INFO: main: >>>>>>> stage Prepare Base Model started<<<<<]
[2023-06-13 18:38:30,354: INFO: common: yaml file:config\config.yaml loaded successfully]
[2023-06-13 18:38:30,396: INFO: common: yaml file:params.yaml loaded successfully]
[2023-06-13 18:38:30,410: INFO: common: created directory at: artifacts]
[2023-06-13 18:38:30,413: INFO: common: created directory at: artifacts/prepare_base_model]
[2023-06-13 18:38:31,303: WARNING: saving_utils: Compiled the loaded model, but the compiled metrics have yet to be built. `model.compile_metrics` will be empty until you train or evaluate the model.]
[2023-06-13 18:38:34,282: INFO: main: <<<<<<stage Prepare Base Model completed >>>>>>>>>>

x==============x]
[2023-06-13 18:38:34,283: INFO: main: **********************]
[2023-06-13 18:38:34,284: INFO: main: >>>>>>>>stage Training started <<<<<<<<<<]
[2023-06-13 18:38:34,289: INFO: common: yaml file:config\config.yaml loaded successfully]
[2023-06-13 18:38:34,317: INFO: common: yaml file:params.yaml loaded successfully]
[2023-06-13 18:38:34,319: INFO: common: created directory at: artifacts]
[2023-06-13 18:38:34,321: INFO: common: created directory at: artifacts\callbacks\checkpoint_dir]
[2023-06-13 18:38:34,323: INFO: common: created directory at: artifacts\callbacks\tensorboard_log_dir]
[2023-06-13 18:38:34,352: INFO: common: created directory at: artifacts\training]
[2023-06-13 18:38:34,356: ERROR: main: module 'keras.api._v2.keras' has no attribute 'model']
Traceback (most recent call last):
  File "main.py", line 36, in <module>
    model_trainer.main()
  File "f:\ineuron\project\chicken-disease-classification\src\chickenClassifier\pipeline\stage_03_training.py", line 21, in main
    training.get_base_model()
  File "f:\ineuron\project\chicken-disease-classification\src\chickenClassifier\components\training.py", line 17, in get_base_model
    self.model = tf.keras.model.load_model(self.config.updated_base_model_path)
AttributeError: module 'keras.api._v2.keras' has no attribute 'model'
[2023-06-13 18:40:00,891: INFO: main: >>>>>>> stage Data Ingestion stage started<<<<<]
[2023-06-13 18:40:00,923: INFO: common: yaml file:config\config.yaml loaded successfully]
[2023-06-13 18:40:00,943: INFO: common: yaml file:params.yaml loaded successfully]
[2023-06-13 18:40:00,958: INFO: common: created directory at: artifacts]
[2023-06-13 18:40:00,984: INFO: common: created directory at: artifacts/data_ingestion]
[2023-06-13 18:40:00,991: INFO: data_ingestion: File already exists of size: ~0 KB]
[2023-06-13 18:40:00,993: INFO: main: <<<<<<stage Data Ingestion stage completed >>>>>>>>>>

x==============x]
[2023-06-13 18:40:01,032: INFO: main: >>>>>>> stage Prepare Base Model started<<<<<]
[2023-06-13 18:40:01,045: INFO: common: yaml file:config\config.yaml loaded successfully]
[2023-06-13 18:40:01,086: INFO: common: yaml file:params.yaml loaded successfully]
[2023-06-13 18:40:01,088: INFO: common: created directory at: artifacts]
[2023-06-13 18:40:01,090: INFO: common: created directory at: artifacts/prepare_base_model]
[2023-06-13 18:40:02,014: WARNING: saving_utils: Compiled the loaded model, but the compiled metrics have yet to be built. `model.compile_metrics` will be empty until you train or evaluate the model.]
[2023-06-13 18:40:05,594: INFO: main: <<<<<<stage Prepare Base Model completed >>>>>>>>>>

x==============x]
[2023-06-13 18:40:05,595: INFO: main: **********************]
[2023-06-13 18:40:05,596: INFO: main: >>>>>>>>stage Training started <<<<<<<<<<]
[2023-06-13 18:40:05,602: INFO: common: yaml file:config\config.yaml loaded successfully]
[2023-06-13 18:40:05,630: INFO: common: yaml file:params.yaml loaded successfully]
[2023-06-13 18:40:05,632: INFO: common: created directory at: artifacts]
[2023-06-13 18:40:05,634: INFO: common: created directory at: artifacts\callbacks\checkpoint_dir]
[2023-06-13 18:40:05,635: INFO: common: created directory at: artifacts\callbacks\tensorboard_log_dir]
[2023-06-13 18:40:05,637: INFO: common: created directory at: artifacts\training]
[2023-06-13 18:40:06,431: ERROR: main: 'Training' object has no attribute 'cofig']
Traceback (most recent call last):
  File "main.py", line 36, in <module>
    model_trainer.main()
  File "f:\ineuron\project\chicken-disease-classification\src\chickenClassifier\pipeline\stage_03_training.py", line 22, in main
    training.train_valid_generator()
  File "f:\ineuron\project\chicken-disease-classification\src\chickenClassifier\components\training.py", line 37, in train_valid_generator
    directory = self.cofig.training_data,
AttributeError: 'Training' object has no attribute 'cofig'
[2023-06-13 18:40:26,431: INFO: main: >>>>>>> stage Data Ingestion stage started<<<<<]
[2023-06-13 18:40:26,472: INFO: common: yaml file:config\config.yaml loaded successfully]
[2023-06-13 18:40:26,517: INFO: common: yaml file:params.yaml loaded successfully]
[2023-06-13 18:40:26,519: INFO: common: created directory at: artifacts]
[2023-06-13 18:40:26,521: INFO: common: created directory at: artifacts/data_ingestion]
[2023-06-13 18:40:26,525: INFO: data_ingestion: File already exists of size: ~0 KB]
[2023-06-13 18:40:26,528: INFO: main: <<<<<<stage Data Ingestion stage completed >>>>>>>>>>

x==============x]
[2023-06-13 18:40:26,563: INFO: main: >>>>>>> stage Prepare Base Model started<<<<<]
[2023-06-13 18:40:26,612: INFO: common: yaml file:config\config.yaml loaded successfully]
[2023-06-13 18:40:26,620: INFO: common: yaml file:params.yaml loaded successfully]
[2023-06-13 18:40:26,662: INFO: common: created directory at: artifacts]
[2023-06-13 18:40:26,668: INFO: common: created directory at: artifacts/prepare_base_model]
[2023-06-13 18:40:27,541: WARNING: saving_utils: Compiled the loaded model, but the compiled metrics have yet to be built. `model.compile_metrics` will be empty until you train or evaluate the model.]
[2023-06-13 18:40:32,247: INFO: main: <<<<<<stage Prepare Base Model completed >>>>>>>>>>

x==============x]
[2023-06-13 18:40:32,249: INFO: main: **********************]
[2023-06-13 18:40:32,249: INFO: main: >>>>>>>>stage Training started <<<<<<<<<<]
[2023-06-13 18:40:32,267: INFO: common: yaml file:config\config.yaml loaded successfully]
[2023-06-13 18:40:32,283: INFO: common: yaml file:params.yaml loaded successfully]
[2023-06-13 18:40:32,285: INFO: common: created directory at: artifacts]
[2023-06-13 18:40:32,287: INFO: common: created directory at: artifacts\callbacks\checkpoint_dir]
[2023-06-13 18:40:32,288: INFO: common: created directory at: artifacts\callbacks\tensorboard_log_dir]
[2023-06-13 18:40:32,316: INFO: common: created directory at: artifacts\training]
[2023-06-13 18:40:33,411: ERROR: main: module 'keras.api._v2.keras' has no attribute 'preproecessing']
Traceback (most recent call last):
  File "main.py", line 36, in <module>
    model_trainer.main()
  File "f:\ineuron\project\chicken-disease-classification\src\chickenClassifier\pipeline\stage_03_training.py", line 22, in main
    training.train_valid_generator()
  File "f:\ineuron\project\chicken-disease-classification\src\chickenClassifier\components\training.py", line 44, in train_valid_generator
    train_datagenerator = tf.keras.preproecessing.image.ImageDataGenerator(
AttributeError: module 'keras.api._v2.keras' has no attribute 'preproecessing'
[2023-06-13 18:41:03,068: INFO: main: >>>>>>> stage Data Ingestion stage started<<<<<]
[2023-06-13 18:41:03,080: INFO: common: yaml file:config\config.yaml loaded successfully]
[2023-06-13 18:41:03,120: INFO: common: yaml file:params.yaml loaded successfully]
[2023-06-13 18:41:03,167: INFO: common: created directory at: artifacts]
[2023-06-13 18:41:03,212: INFO: common: created directory at: artifacts/data_ingestion]
[2023-06-13 18:41:03,261: INFO: data_ingestion: File already exists of size: ~0 KB]
[2023-06-13 18:41:03,281: INFO: main: <<<<<<stage Data Ingestion stage completed >>>>>>>>>>

x==============x]
[2023-06-13 18:41:03,317: INFO: main: >>>>>>> stage Prepare Base Model started<<<<<]
[2023-06-13 18:41:03,328: INFO: common: yaml file:config\config.yaml loaded successfully]
[2023-06-13 18:41:03,333: INFO: common: yaml file:params.yaml loaded successfully]
[2023-06-13 18:41:03,372: INFO: common: created directory at: artifacts]
[2023-06-13 18:41:03,445: INFO: common: created directory at: artifacts/prepare_base_model]
[2023-06-13 18:41:04,405: WARNING: saving_utils: Compiled the loaded model, but the compiled metrics have yet to be built. `model.compile_metrics` will be empty until you train or evaluate the model.]
[2023-06-13 18:41:08,166: INFO: main: <<<<<<stage Prepare Base Model completed >>>>>>>>>>

x==============x]
[2023-06-13 18:41:08,167: INFO: main: **********************]
[2023-06-13 18:41:08,167: INFO: main: >>>>>>>>stage Training started <<<<<<<<<<]
[2023-06-13 18:41:08,187: INFO: common: yaml file:config\config.yaml loaded successfully]
[2023-06-13 18:41:08,201: INFO: common: yaml file:params.yaml loaded successfully]
[2023-06-13 18:41:08,203: INFO: common: created directory at: artifacts]
[2023-06-13 18:41:08,206: INFO: common: created directory at: artifacts\callbacks\checkpoint_dir]
[2023-06-13 18:41:08,233: INFO: common: created directory at: artifacts\callbacks\tensorboard_log_dir]
[2023-06-13 18:41:08,234: INFO: common: created directory at: artifacts\training]
[2023-06-13 18:41:09,208: ERROR: main: 'Training' object has no attribute 'train_generator']
Traceback (most recent call last):
  File "main.py", line 36, in <module>
    model_trainer.main()
  File "f:\ineuron\project\chicken-disease-classification\src\chickenClassifier\pipeline\stage_03_training.py", line 23, in main
    training.train(
  File "f:\ineuron\project\chicken-disease-classification\src\chickenClassifier\components\training.py", line 68, in train
    self.steps_per_epoch = self.train_generator.samples // self.train_generator.batch_size
AttributeError: 'Training' object has no attribute 'train_generator'
[2023-06-13 18:42:48,628: INFO: main: >>>>>>> stage Data Ingestion stage started<<<<<]
[2023-06-13 18:42:48,673: INFO: common: yaml file:config\config.yaml loaded successfully]
[2023-06-13 18:42:48,682: INFO: common: yaml file:params.yaml loaded successfully]
[2023-06-13 18:42:48,695: INFO: common: created directory at: artifacts]
[2023-06-13 18:42:48,720: INFO: common: created directory at: artifacts/data_ingestion]
[2023-06-13 18:42:48,726: INFO: data_ingestion: File already exists of size: ~0 KB]
[2023-06-13 18:42:48,729: INFO: main: <<<<<<stage Data Ingestion stage completed >>>>>>>>>>

x==============x]
[2023-06-13 18:42:48,767: INFO: main: >>>>>>> stage Prepare Base Model started<<<<<]
[2023-06-13 18:42:48,818: INFO: common: yaml file:config\config.yaml loaded successfully]
[2023-06-13 18:42:48,882: INFO: common: yaml file:params.yaml loaded successfully]
[2023-06-13 18:42:48,929: INFO: common: created directory at: artifacts]
[2023-06-13 18:42:48,945: INFO: common: created directory at: artifacts/prepare_base_model]
[2023-06-13 18:42:49,978: WARNING: saving_utils: Compiled the loaded model, but the compiled metrics have yet to be built. `model.compile_metrics` will be empty until you train or evaluate the model.]
[2023-06-13 18:42:53,392: INFO: main: <<<<<<stage Prepare Base Model completed >>>>>>>>>>

x==============x]
[2023-06-13 18:42:53,393: INFO: main: **********************]
[2023-06-13 18:42:53,394: INFO: main: >>>>>>>>stage Training started <<<<<<<<<<]
[2023-06-13 18:42:53,423: INFO: common: yaml file:config\config.yaml loaded successfully]
[2023-06-13 18:42:53,429: INFO: common: yaml file:params.yaml loaded successfully]
[2023-06-13 18:42:53,430: INFO: common: created directory at: artifacts]
[2023-06-13 18:42:53,432: INFO: common: created directory at: artifacts\callbacks\checkpoint_dir]
[2023-06-13 18:42:53,433: INFO: common: created directory at: artifacts\callbacks\tensorboard_log_dir]
[2023-06-13 18:42:53,448: INFO: common: created directory at: artifacts\training]
[2023-06-13 18:42:54,400: ERROR: main: 'ImageDataGenerator' object is not callable]
Traceback (most recent call last):
  File "main.py", line 36, in <module>
    model_trainer.main()
  File "f:\ineuron\project\chicken-disease-classification\src\chickenClassifier\pipeline\stage_03_training.py", line 22, in main
    training.train_valid_generator()
  File "f:\ineuron\project\chicken-disease-classification\src\chickenClassifier\components\training.py", line 56, in train_valid_generator
    self.train_generator = train_datagenerator(
TypeError: 'ImageDataGenerator' object is not callable
[2023-06-13 18:43:53,910: INFO: main: >>>>>>> stage Data Ingestion stage started<<<<<]
[2023-06-13 18:43:53,922: INFO: common: yaml file:config\config.yaml loaded successfully]
[2023-06-13 18:43:53,977: INFO: common: yaml file:params.yaml loaded successfully]
[2023-06-13 18:43:54,000: INFO: common: created directory at: artifacts]
[2023-06-13 18:43:54,006: INFO: common: created directory at: artifacts/data_ingestion]
[2023-06-13 18:43:54,046: INFO: data_ingestion: File already exists of size: ~0 KB]
[2023-06-13 18:43:54,051: INFO: main: <<<<<<stage Data Ingestion stage completed >>>>>>>>>>

x==============x]
[2023-06-13 18:43:54,054: INFO: main: >>>>>>> stage Prepare Base Model started<<<<<]
[2023-06-13 18:43:54,147: INFO: common: yaml file:config\config.yaml loaded successfully]
[2023-06-13 18:43:54,204: INFO: common: yaml file:params.yaml loaded successfully]
[2023-06-13 18:43:54,219: INFO: common: created directory at: artifacts]
[2023-06-13 18:43:54,252: INFO: common: created directory at: artifacts/prepare_base_model]
[2023-06-13 18:43:55,428: WARNING: saving_utils: Compiled the loaded model, but the compiled metrics have yet to be built. `model.compile_metrics` will be empty until you train or evaluate the model.]
[2023-06-13 18:43:58,792: INFO: main: <<<<<<stage Prepare Base Model completed >>>>>>>>>>

x==============x]
[2023-06-13 18:43:58,794: INFO: main: **********************]
[2023-06-13 18:43:58,794: INFO: main: >>>>>>>>stage Training started <<<<<<<<<<]
[2023-06-13 18:43:58,799: INFO: common: yaml file:config\config.yaml loaded successfully]
[2023-06-13 18:43:58,825: INFO: common: yaml file:params.yaml loaded successfully]
[2023-06-13 18:43:58,827: INFO: common: created directory at: artifacts]
[2023-06-13 18:43:58,829: INFO: common: created directory at: artifacts\callbacks\checkpoint_dir]
[2023-06-13 18:43:58,830: INFO: common: created directory at: artifacts\callbacks\tensorboard_log_dir]
[2023-06-13 18:43:58,865: INFO: common: created directory at: artifacts\training]
[2023-06-13 18:44:00,497: ERROR: main: unsupported operand type(s) for //: 'int' and 'BoxList']
Traceback (most recent call last):
  File "main.py", line 36, in <module>
    model_trainer.main()
  File "f:\ineuron\project\chicken-disease-classification\src\chickenClassifier\pipeline\stage_03_training.py", line 23, in main
    training.train(
  File "f:\ineuron\project\chicken-disease-classification\src\chickenClassifier\components\training.py", line 68, in train
    self.steps_per_epoch = self.train_generator.samples // self.train_generator.batch_size
TypeError: unsupported operand type(s) for //: 'int' and 'BoxList'
[2023-06-13 19:32:03,163: INFO: main: >>>>>>> stage Data Ingestion stage started<<<<<]
[2023-06-13 19:32:03,307: INFO: common: yaml file:config\config.yaml loaded successfully]
[2023-06-13 19:32:03,315: INFO: common: yaml file:params.yaml loaded successfully]
[2023-06-13 19:32:03,317: INFO: common: created directory at: artifacts]
[2023-06-13 19:32:03,318: INFO: common: created directory at: artifacts/data_ingestion]
[2023-06-13 19:32:03,321: INFO: data_ingestion: File already exists of size: ~0 KB]
[2023-06-13 19:32:03,322: INFO: main: <<<<<<stage Data Ingestion stage completed >>>>>>>>>>

x==============x]
[2023-06-13 19:32:03,323: INFO: main: >>>>>>> stage Prepare Base Model started<<<<<]
[2023-06-13 19:32:03,330: INFO: common: yaml file:config\config.yaml loaded successfully]
[2023-06-13 19:32:03,333: INFO: common: yaml file:params.yaml loaded successfully]
[2023-06-13 19:32:03,334: INFO: common: created directory at: artifacts]
[2023-06-13 19:32:03,335: INFO: common: created directory at: artifacts/prepare_base_model]
[2023-06-13 19:32:04,587: WARNING: saving_utils: Compiled the loaded model, but the compiled metrics have yet to be built. `model.compile_metrics` will be empty until you train or evaluate the model.]
[2023-06-13 19:32:06,498: INFO: main: <<<<<<stage Prepare Base Model completed >>>>>>>>>>

x==============x]
[2023-06-13 19:32:06,499: INFO: main: **********************]
[2023-06-13 19:32:06,500: INFO: main: >>>>>>>>stage Training started <<<<<<<<<<]
[2023-06-13 19:32:06,518: INFO: common: yaml file:config\config.yaml loaded successfully]
[2023-06-13 19:32:06,534: INFO: common: yaml file:params.yaml loaded successfully]
[2023-06-13 19:32:06,536: INFO: common: created directory at: artifacts]
[2023-06-13 19:32:06,537: INFO: common: created directory at: artifacts\callbacks\checkpoint_dir]
[2023-06-13 19:32:06,538: INFO: common: created directory at: artifacts\callbacks\tensorboard_log_dir]
[2023-06-13 19:32:06,540: INFO: common: created directory at: artifacts\training]
[2023-06-13 19:32:07,848: ERROR: main: 'Training' object has no attribute 'validation_generator']
Traceback (most recent call last):
  File "main.py", line 36, in <module>
    model_trainer.main()
  File "f:\ineuron\project\chicken-disease-classification\src\chickenClassifier\pipeline\stage_03_training.py", line 23, in main
    training.train(
  File "f:\ineuron\project\chicken-disease-classification\src\chickenClassifier\components\training.py", line 76, in train
    validation_data = self.validation_generator,
AttributeError: 'Training' object has no attribute 'validation_generator'
[2023-06-13 19:32:49,605: INFO: main: >>>>>>> stage Data Ingestion stage started<<<<<]
[2023-06-13 19:32:49,633: INFO: common: yaml file:config\config.yaml loaded successfully]
[2023-06-13 19:32:49,650: INFO: common: yaml file:params.yaml loaded successfully]
[2023-06-13 19:32:49,652: INFO: common: created directory at: artifacts]
[2023-06-13 19:32:49,653: INFO: common: created directory at: artifacts/data_ingestion]
[2023-06-13 19:32:49,668: INFO: data_ingestion: File already exists of size: ~0 KB]
[2023-06-13 19:32:49,674: INFO: main: <<<<<<stage Data Ingestion stage completed >>>>>>>>>>

x==============x]
[2023-06-13 19:32:49,675: INFO: main: >>>>>>> stage Prepare Base Model started<<<<<]
[2023-06-13 19:32:49,702: INFO: common: yaml file:config\config.yaml loaded successfully]
[2023-06-13 19:32:49,725: INFO: common: yaml file:params.yaml loaded successfully]
[2023-06-13 19:32:49,728: INFO: common: created directory at: artifacts]
[2023-06-13 19:32:49,744: INFO: common: created directory at: artifacts/prepare_base_model]
[2023-06-13 19:32:50,539: WARNING: saving_utils: Compiled the loaded model, but the compiled metrics have yet to be built. `model.compile_metrics` will be empty until you train or evaluate the model.]
[2023-06-13 19:32:53,898: INFO: main: <<<<<<stage Prepare Base Model completed >>>>>>>>>>

x==============x]
[2023-06-13 19:32:53,899: INFO: main: **********************]
[2023-06-13 19:32:53,900: INFO: main: >>>>>>>>stage Training started <<<<<<<<<<]
[2023-06-13 19:32:53,914: INFO: common: yaml file:config\config.yaml loaded successfully]
[2023-06-13 19:32:53,930: INFO: common: yaml file:params.yaml loaded successfully]
[2023-06-13 19:32:53,932: INFO: common: created directory at: artifacts]
[2023-06-13 19:32:53,933: INFO: common: created directory at: artifacts\callbacks\checkpoint_dir]
[2023-06-13 19:32:53,935: INFO: common: created directory at: artifacts\callbacks\tensorboard_log_dir]
[2023-06-13 19:32:53,937: INFO: common: created directory at: artifacts\training]
